Workbook

Sheet Normas
A1: Aprendiz de Excel - Mundial de Clubes 2025
B3: 2$ por participar. Imprescindible entregar resultados y se pagara al final del torneo al ganador.
C5: Puntos | D5: Puntos máx | G5: Reparto de Premios
B6: Signo de partido (1x2) en FG | C6: 3 | D6: =C6*6*8 -> 144 | G6: Fase de grupos | I6: Fase de eliminatorias | K6: General
B7: Número goles L ó V en FG | C7: 0 | D7: =C7*2*6*8 -> 0 | G7: Primero | H7: 1 | I7: Primero | J7: 1 | K7: Primero | L7: 1
B8: Puntos adicionales resultado exacto FG | C8: 5 | D8: =C8*6*8 -> 240 | G8: Segundo | H8: 0 | I8: Segundo | J8: 0 | K8: Segundo | L8: 0
B9: Signo de partido (1x2) en Octavos | C9: 9 | D9: =C9*8 -> 72 | G9: Tercero | H9: 0 | I9: Tercero | J9: 0 | K9: Tercero | L9: 0
B10: Número goles L ó V en Octavos | C10: 0 | D10: =C10*2*8 -> 0 | G10: Cuarto | H10: 0 | I10: Cuarto | J10: 0 | K10: Cuarto | L10: 0
B11: Puntos adicionales resultado exacto Octavos | C11: 15 | D11: =C11*8 -> 120 | G11: Quinto | H11: 0 | I11: Quinto | J11: 0 | K11: Quinto | L11: 0
B12: Signo de partido (1x2) en Cuartos | C12: 9 | D12: =C12*4 -> 36 | G12: Último | H12: 0 | I12: Último | J12: 0 | K12: Último | L12: 0.02
B13: Número goles L ó V en Cuartos | C13: 0 | D13: =C13*2*4 -> 0 | G13: Ganador de cada grupo | H13: 0
B14: Puntos adicionales resultado exacto Cuartos | C14: =+C11 -> 15 | D14: =C14*4 -> 60 | G14: Total | H14: =SUM(H7:H12)+H13*8 -> 1 | I14: Total | J14: =SUM(J7:J12) -> 1 | K14: Total | L14: =SUM(L7:L12) -> 1.02
B15: Signo de partido (1x2) en Semis | C15: 9 | D15: =C15*2 -> 18
B16: Número goles L ó V en Semis | C16: 0 | D16: =C16*2*2 -> 0
B17: Puntos adicionales resultado exacto Semis | C17: 15 | D17: =C17*2 -> 30
B18: Signo de partido (1x2) en Final | C18: 9 | D18: =C18 -> 9
B19: Número goles L ó V en Final | C19: 0 | D19: =C19*2 -> 0 | I19: Aprendiz de Excel
B20: Puntos adicionales resultado exacto Final | C20: 15 | D20: =C20 -> 15
B21: Equipos campeones de grupo | C21: 15 | D21: =+C21*8 -> 120 | I21: Vídeo YouTube
B22: Equipos que pasan a octavos | C22: 20 | D22: =+C22*8 -> 160
B23: Equipos que pasan a cuartos | C23: 25 | D23: =+C23*8 -> 200
B24: Equipos que pasan a semis | C24: 30 | D24: =+C24*4 -> 120
B25: Equipos que juegan la final | C25: 35 | D25: =+C25*2 -> 70
B26: Campeón | C26: 50 | D26: =+C26 -> 50
B28: Nombre | C28: robstan luibo
B30: Mail | C30: robstanlubo@gmail.com
B32: Teléfono | C32: 4126737263 | F32: UTC | G32: 2
C34: Puntos | D34: Puntos máx
B35: Goleador | C35: 15 | D35: 15 | E35: halland
B36: Max. Asistidor | C36: 15 | D36: 15 | E36: reinders
B37: MVP del torneo | C37: 15 | D37: 15 | E37: MBAPPE
B38: Portero de oro | C38: 15 | D38: 15 | E38: COURTOIS
B39: MOP del torneo (Jugador decepcion) | C39: 15 | D39: 15 | E39: DEMBELE
B40: Equipo San marino (peor equipo de la competicion) | C40: 15 | D40: 15 | E40: WYDAD

Sheet Previa
A1: Aprendiz de Excel - Mundial de Clubes 2025
C8: # | D8: Fechas | E8: Horas | H8: CUARTOS | S8: Estadios | U8: Ganadores
A10: 1A | B10: 2B | C10: 0 | D10: =VLOOKUP(C10,Aux!M:AH,4,0) -> 45809.188 | E10: =VLOOKUP(C10,Aux!M:AH,4,0) -> 45809.188 | G10: =IFERROR(VLOOKUP(H10,Aux!$A:$X,8,0),"") -> #VALUE! | H10: Los Angeles | I10: =IFERROR(VLOOKUP(H10,Aux!$A:$C,3,0),"") -> #VALUE! | K10: 2 | L10: - | M10: 1 | O10: =IFERROR(VLOOKUP(P10,Aux!$A:$C,3,0),"") -> #VALUE! | P10: América | Q10: =IFERROR(VLOOKUP(P10,Aux!$A:$X,8,0),"") -> #VALUE! | S10: =+VLOOKUP(C10,Aux!M:AZ,7,0) -> BMO Stadium | U10: =IF(OR(K10="",M10=""),"",IF(K10>M10,H10,IF(K10<M10,P10,IF(OR(K11="",M11=""),"",IF(K11=M11,"",IF(K11>M11,H10,P10)))))) -> Los Angeles
H11: Penaltis | L11: -

Sheet A
A1: Aprendiz de Excel - Mundial de Clubes 2025
AY5: 2º | BA5: =VLOOKUP(BA8,$AH$10:$AW$16,15,0) -> 0 | BB5: =VLOOKUP(BB8,$AH$10:$AW$16,15,0) -> 0 | BC5: =VLOOKUP(BC8,$AH$10:$AW$16,15,0) -> 0.10001 | BD5: =VLOOKUP(BD8,$AH$10:$AW$16,15,0) -> 0.10001
AH6: A | AY6: 1º | BA6: =VLOOKUP(BA8,$AH$10:$AW$16,14,0) -> 0 | BB6: =VLOOKUP(BB8,$AH$10:$AW$16,14,0) -> 3 | BC6: =VLOOKUP(BC8,$AH$10:$AW$16,14,0) -> 7 | BD6: =VLOOKUP(BD8,$AH$10:$AW$16,14,0) -> 7
B7: # | C7: Fechas | D7: Horas | E7: PARTIDOS | R7: Estadios | T7: POSICIONES
W8: Pts. | X8: Gan. | Y8: Emp. | Z8: Per. | AA8: GF | AB8: GC | AC8: Dif. | AH8: País | AI8: J | AJ8: Pts. | AK8: Gan. | AL8: Emp. | AM8: Per. | AN8: GF | AO8: GC | AP8: DG | AQ8: JL | AR8: ED | AU8: 1º Criterio | AV8: 2º Criterio | AW8: 3º Criterio | BA8: =AH10 -> Al-Ahly | BB8: =AH12 -> Inter Miami | BC8: =AH14 -> Palmeiras | BD8: =AH16 -> Porto
B9: {=_xlfn.REDUCE("",_xlfn.TAKE(_xlfn._xlws.FILTER(Aux!M:T,Aux!T:T=AH6),,1),_xlfn.LAMBDA(_xlpm.t,_xlpm.p,_xlfn.VSTACK(_xlpm.t,_xlpm.p,"")))}
B10: 1 | C10: =VLOOKUP(B10,Aux!M:AH,4,0) -> 45823.083 | D10: =VLOOKUP(B10,Aux!M:AH,4,0) -> 45823.083 | F10: =IFERROR(VLOOKUP(G10,Aux!$A:$X,8,0),"") -> #VALUE! | G10: =VLOOKUP(B10,Aux!M:Y,5,0) -> Al-Ahly | H10: =IFERROR(VLOOKUP(G10,Aux!$A:$C,3,0),"") -> #VALUE! | J10: 0 | K10: - | L10: 2 | N10: =IFERROR(VLOOKUP(O10,Aux!$A:$C,3,0),"") -> #VALUE! | O10: =VLOOKUP(B10,Aux!M:Y,6,0) -> Inter Miami | P10: =IFERROR(VLOOKUP(O10,Aux!$A:$X,8,0),"") -> #VALUE! | R10: =VLOOKUP(B10,Aux!M:Y,7,0) -> Hard Rock Stadium | T10: =INDEX($AH$10:$AH$17,MATCH(1,$AY$10:$AY$16,0)) -> Palmeiras | U10: =IFERROR(VLOOKUP(T10,Aux!A:C,3,0),"") -> #VALUE! | W10: =VLOOKUP($T10,$AH$10:$AO$16,3,0) -> 7 | X10: =VLOOKUP($T10,$AH$10:$AO$16,4,0) -> 2 | Y10: =VLOOKUP($T10,$AH$10:$AO$16,5,0) -> 1 | Z10: =VLOOKUP($T10,$AH$10:$AO$16,6,0) -> 0 | AA10: =VLOOKUP($T10,$AH$10:$AO$16,7,0) -> 6 | AB10: =VLOOKUP($T10,$AH$10:$AO$16,8,0) -> 3 | AC10: =AA10-AB10 -> 3 | AG10: 1 | AH10: =VLOOKUP($AH$6&AG10,Aux!Z:AA,2,0) -> Al-Ahly | AI10: =AK10+AL10+AM10 -> 3 | AJ10: =AK10*3+AL10 -> 0 | AK10: {=SUM(($G$10:$G$23=$AH10)*($J$10:$J$23>$L$10:$L$23)+($O$10:$O$23=$AH10)*($J$10:$J$23<$L$10:$L$23))} -> 0 | AL10: {=SUM(($G$10:$G$23=$AH10)*($J$10:$J$23=$L$10:$L$23)*($J$10:$J$23<>"")+($O$10:$O$23=$AH10)*($J$10:$J$23=$L$10:$L$23)*($J$10:$J$23<>""))} -> 0 | AM10: {=SUM(($G$10:$G$23=$AH10)*($J$10:$J$23<$L$10:$L$23)+($O$10:$O$23=$AH10)*($J$10:$J$23>$L$10:$L$23))} -> 3 | AN10: {=SUM(($G$10:$G$23=$AH10)*($J$10:$J$23)+($O$10:$O$23=$AH10)*($L$10:$L$23))} -> 0 | AO10: {=SUM(($G$10:$G$23=$AH10)*($L$10:$L$23)+($O$10:$O$23=$AH10)*($J$10:$J$23))} -> 6 | AP10: =AN10-AO10 -> -6 | AQ10: 0 | AR10: =+AW10+AV10+AU10 -> -2e-06 | AU10: =+AJ10 -> 0 | AV10: =SUMIFS($BA10:$BD10,$BA$6:$BD$6,AJ10)/1000 -> 0 | AW10: =SUMIFS($BA10:$BD10,$BA$5:$BD$5,AV10)/1000000 -> -2e-06 | AX10: =_xlfn.RANK.EQ(AJ10,$AJ$10:$AJ$16)+_xlfn.RANK.EQ(AR10,$AR$10:$AR$16)/10+_xlfn.RANK.EQ(AP10,$AP$10:$AP$16)/1000+_xlfn.RANK.EQ(AN10,$AN$10:$AN$16)/100000+_xlfn.RANK.EQ(AQ10,$AQ$10:$AQ$16)/100000+ROW()/1000000 -> 4.40406 | AY10: =_xlfn.RANK.EQ(AX10,$AX$10:$AX$16,1) -> 4 | BA10: {=(SUM(($G$10:$G$23=$AH10)*($J$10:$J$23>$L$10:$L$23)*($O$10:$O$23=BA$8)+($O$10:$O$23=$AH10)*($J$10:$J$23<$L$10:$L$23)*($G$10:$G$23=BA$8)))*300+ (SUM(($G$10:$G$23=$AH10)*($J$10:$J$23=$L$10:$L$23)*($O$10:$O$23=BA$8)+($O$10:$O$23=$AH10)*($J$10:$J$23=$L$10:$L$23)*($G$10:$G$23=BA$8)))*100 +SUM(($G$10:$G$23=$AH10)*($J$10:$J$23)*($O$10:$O$23=BA$8)+($O$10:$O$23=$AH10)*($L$10:$L$23)*($G$10:$G$23=BA$8)) -SUM(($G$10:$G$23=$AH10)*($L$10:$L$23)*($O$10:$O$23=BA$8)+($O$10:$O$23=$AH10)*($J$10:$J$23)*($G$10:$G$23=BA$8)) +SUM(($G$10:$G$23=$AH10)*($J$10:$J$23)*($O$10:$O$23=BA$8)+($O$10:$O$23=$AH10)*($L$10:$L$23)*($G$10:$G$23=BA$8))/100} -> 0 | BB10: {=(SUM(($G$10:$G$23=$AH10)*($J$10:$J$23>$L$10:$L$23)*($O$10:$O$23=BB$8)+($O$10:$O$23=$AH10)*($J$10:$J$23<$L$10:$L$23)*($G$10:$G$23=BB$8)))*300+ (SUM(($G$10:$G$23=$AH10)*($J$10:$J$23=$L$10:$L$23)*($O$10:$O$23=BB$8)+($O$10:$O$23=$AH10)*($J$10:$J$23=$L$10:$L$23)*($G$10:$G$23=BB$8)))*100 +SUM(($G$10:$G$23=$AH10)*($J$10:$J$23)*($O$10:$O$23=BB$8)+($O$10:$O$23=$AH10)*($L$10:$L$23)*($G$10:$G$23=BB$8)) -SUM(($G$10:$G$23=$AH10)*($L$10:$L$23)*($O$10:$O$23=BB$8)+($O$10:$O$23=$AH10)*($J$10:$J$23)*($G$10:$G$23=BB$8)) +SUM(($G$10:$G$23=$AH10)*($J$10:$J$23)*($O$10:$O$23=BB$8)+($O$10:$O$23=$AH10)*($L$10:$L$23)*($G$10:$G$23=BB$8))/100} -> -2 | BC10: {=(SUM(($G$10:$G$23=$AH10)*($J$10:$J$23>$L$10:$L$23)*($O$10:$O$23=BC$8)+($O$10:$O$23=$AH10)*($J$10:$J$23<$L$10:$L$23)*($G$10:$G$23=BC$8)))*300+ (SUM(($G$10:$G$23=$AH10)*($J$10:$J$23=$L$10:$L$23)*($O$10:$O$23=BC$8)+($O$10:$O$23=$AH10)*($J$10:$J$23=$L$10:$L$23)*($G$10:$G$23=BC$8)))*100 +SUM(($G$10:$G$23=$AH10)*($J$10:$J$23)*($O$10:$O$23=BC$8)+($O$10:$O$23=$AH10)*($L$10:$L$23)*($G$10:$G$23=BC$8)) -SUM(($G$10:$G$23=$AH10)*($L$10:$L$23)*($O$10:$O$23=BC$8)+($O$10:$O$23=$AH10)*($J$10:$J$23)*($G$10:$G$23=BC$8)) +SUM(($G$10:$G$23=$AH10)*($J$10:$J$23)*($O$10:$O$23=BC$8)+($O$10:$O$23=$AH10)*($L$10:$L$23)*($G$10:$G$23=BC$8))/100} -> -2 | BD10: {=(SUM(($G$10:$G$23=$AH10)*($J$10:$J$23>$L$10:$L$23)*($O$10:$O$23=BD$8)+($O$10:$O$23=$AH10)*($J$10:$J$23<$L$10:$L$23)*($G$10:$G$23=BD$8)))*300+ (SUM(($G$10:$G$23=$AH10)*($J$10:$J$23=$L$10:$L$23)*($O$10:$O$23=BD$8)+($O$10:$O$23=$AH10)*($J$10:$J$23=$L$10:$L$23)*($G$10:$G$23=BD$8)))*100 +SUM(($G$10:$G$23=$AH10)*($J$10:$J$23)*($O$10:$O$23=BD$8)+($O$10:$O$23=$AH10)*($L$10:$L$23)*($G$10:$G$23=BD$8)) -SUM(($G$10:$G$23=$AH10)*($L$10:$L$23)*($O$10:$O$23=BD$8)+($O$10:$O$23=$AH10)*($J$10:$J$23)*($G$10:$G$23=BD$8)) +SUM(($G$10:$G$23=$AH10)*($J$10:$J$23)*($O$10:$O$23=BD$8)+($O$10:$O$23=$AH10)*($L$10:$L$23)*($G$10:$G$23=BD$8))/100} -> -2
B12: 4 | C12: =VLOOKUP(B12,Aux!M:AH,4,0) -> 45824 | D12: =VLOOKUP(B12,Aux!M:AH,4,0) -> 45824 | F12: =IFERROR(VLOOKUP(G12,Aux!$A:$X,8,0),"") -> #VALUE! | G12: =VLOOKUP(B12,Aux!M:Y,5,0) -> Palmeiras | H12: =IFERROR(VLOOKUP(G12,Aux!$A:$C,3,0),"") -> #VALUE! | J12: 1 | K12: - | L12: 1 | N12: =IFERROR(VLOOKUP(O12,Aux!$A:$C,3,0),"") -> #VALUE! | O12: =VLOOKUP(B12,Aux!M:Y,6,0) -> Porto | P12: =IFERROR(VLOOKUP(O12,Aux!$A:$X,8,0),"") -> #VALUE! | R12: =VLOOKUP(B12,Aux!M:Y,7,0) -> MetLife Stadium | T12: =INDEX($AH$10:$AH$17,MATCH(2,$AY$10:$AY$16,0)) -> Porto | U12: =IFERROR(VLOOKUP(T12,Aux!A:C,3,0),"") -> #VALUE! | W12: =VLOOKUP($T12,$AH$10:$AO$16,3,0) -> 7 | X12: =VLOOKUP($T12,$AH$10:$AO$16,4,0) -> 2 | Y12: =VLOOKUP($T12,$AH$10:$AO$16,5,0) -> 1 | Z12: =VLOOKUP($T12,$AH$10:$AO$16,6,0) -> 0 | AA12: =VLOOKUP($T12,$AH$10:$AO$16,7,0) -> 5 | AB12: =VLOOKUP($T12,$AH$10:$AO$16,8,0) -> 2 | AC12: =AA12-AB12 -> 3 | AG12: 2 | AH12: =VLOOKUP($AH$6&AG12,Aux!Z:AA,2,0) -> Inter Miami | AI12: =AK12+AL12+AM12 -> 3 | AJ12: =AK12*3+AL12 -> 3 | AK12: {=SUM(($G$10:$G$23=$AH12)*($J$10:$J$23>$L$10:$L$23)+($O$10:$O$23=$AH12)*($J$10:$J$23<$L$10:$L$23))} -> 1 | AL12: {=SUM(($G$10:$G$23=$AH12)*($J$10:$J$23=$L$10:$L$23)*($J$10:$J$23<>"")+($O$10:$O$23=$AH12)*($J$10:$J$23=$L$10:$L$23)*($J$10:$J$23<>""))} -> 0 | AM12: {=SUM(($G$10:$G$23=$AH12)*($J$10:$J$23<$L$10:$L$23)+($O$10:$O$23=$AH12)*($J$10:$J$23>$L$10:$L$23))} -> 2 | AN12: {=SUM(($G$10:$G$23=$AH12)*($J$10:$J$23)+($O$10:$O$23=$AH12)*($L$10:$L$23))} -> 5 | AO12: {=SUM(($G$10:$G$23=$AH12)*($L$10:$L$23)+($O$10:$O$23=$AH12)*($J$10:$J$23))} -> 5 | AP12: =AN12-AO12 -> 0 | AQ12: 0 | AR12: =+AW12+AV12+AU12 -> 3.000302 | AU12: =+AJ12 -> 3 | AV12: =SUMIFS($BA12:$BD12,$BA$6:$BD$6,AJ12)/1000 -> 0 | AW12: =SUMIFS($BA12:$BD12,$BA$5:$BD$5,AV12)/1000000 -> 0.00030202 | AX12: =_xlfn.RANK.EQ(AJ12,$AJ$10:$AJ$16)+_xlfn.RANK.EQ(AR12,$AR$10:$AR$16)/10+_xlfn.RANK.EQ(AP12,$AP$10:$AP$16)/1000+_xlfn.RANK.EQ(AN12,$AN$10:$AN$16)/100000+_xlfn.RANK.EQ(AQ12,$AQ$10:$AQ$16)/100000+ROW()/1000000 -> 3.303042 | AY12: =_xlfn.RANK.EQ(AX12,$AX$10:$AX$16,1) -> 3 | BA12: {=(SUM(($G$10:$G$23=$AH12)*($J$10:$J$23>$L$10:$L$23)*($O$10:$O$23=BA$8)+($O$10:$O$23=$AH12)*($J$10:$J$23<$L$10:$L$23)*($G$10:$G$23=BA$8)))*300+ (SUM(($G$10:$G$23=$AH12)*($J$10:$J$23=$L$10:$L$23)*($O$10:$O$23=BA$8)+($O$10:$O$23=$AH12)*($J$10:$J$23=$L$10:$L$23)*($G$10:$G$23=BA$8)))*100 +SUM(($G$10:$G$23=$AH12)*($J$10:$J$23)*($O$10:$O$23=BA$8)+($O$10:$O$23=$AH12)*($L$10:$L$23)*($G$10:$G$23=BA$8)) -SUM(($G$10:$G$23=$AH12)*($L$10:$L$23)*($O$10:$O$23=BA$8)+($O$10:$O$23=$AH12)*($J$10:$J$23)*($G$10:$G$23=BA$8)) +SUM(($G$10:$G$23=$AH12)*($J$10:$J$23)*($O$10:$O$23=BA$8)+($O$10:$O$23=$AH12)*($L$10:$L$23)*($G$10:$G$23=BA$8))/100} -> 302.02 | BB12: {=(SUM(($G$10:$G$23=$AH12)*($J$10:$J$23>$L$10:$L$23)*($O$10:$O$23=BB$8)+($O$10:$O$23=$AH12)*($J$10:$J$23<$L$10:$L$23)*($G$10:$G$23=BB$8)))*300+ (SUM(($G$10:$G$23=$AH12)*($J$10:$J$23=$L$10:$L$23)*($O$10:$O$23=BB$8)+($O$10:$O$23=$AH12)*($J$10:$J$23=$L$10:$L$23)*($G$10:$G$23=BB$8)))*100 +SUM(($G$10:$G$23=$AH12)*($J$10:$J$23)*($O$10:$O$23=BB$8)+($O$10:$O$23=$AH12)*($L$10:$L$23)*($G$10:$G$23=BB$8)) -SUM(($G$10:$G$23=$AH12)*($L$10:$L$23)*($O$10:$O$23=BB$8)+($O$10:$O$23=$AH12)*($J$10:$J$23)*($G$10:$G$23=BB$8)) +SUM(($G$10:$G$23=$AH12)*($J$10:$J$23)*($O$10:$O$23=BB$8)+($O$10:$O$23=$AH12)*($L$10:$L$23)*($G$10:$G$23=BB$8))/100} -> 0 | BC12: {=(SUM(($G$10:$G$23=$AH12)*($J$10:$J$23>$L$10:$L$23)*($O$10:$O$23=BC$8)+($O$10:$O$23=$AH12)*($J$10:$J$23<$L$10:$L$23)*($G$10:$G$23=BC$8)))*300+ (SUM(($G$10:$G$23=$AH12)*($J$10:$J$23=$L$10:$L$23)*($O$10:$O$23=BC$8)+($O$10:$O$23=$AH12)*($J$10:$J$23=$L$10:$L$23)*($G$10:$G$23=BC$8)))*100 +SUM(($G$10:$G$23=$AH12)*($J$10:$J$23)*($O$10:$O$23=BC$8)+($O$10:$O$23=$AH12)*($L$10:$L$23)*($G$10:$G$23=BC$8)) -SUM(($G$10:$G$23=$AH12)*($L$10:$L$23)*($O$10:$O$23=BC$8)+($O$10:$O$23=$AH12)*($J$10:$J$23)*($G$10:$G$23=BC$8)) +SUM(($G$10:$G$23=$AH12)*($J$10:$J$23)*($O$10:$O$23=BC$8)+($O$10:$O$23=$AH12)*($L$10:$L$23)*($G$10:$G$23=BC$8))/100} -> -0.98 | BD12: {=(SUM(($G$10:$G$23=$AH12)*($J$10:$J$23>$L$10:$L$23)*($O$10:$O$23=BD$8)+($O$10:$O$23=$AH12)*($J$10:$J$23<$L$10:$L$23)*($G$10:$G$23=BD$8)))*300+ (SUM(($G$10:$G$23=$AH12)*($J$10:$J$23=$L$10:$L$23)*($O$10:$O$23=BD$8)+($O$10:$O$23=$AH12)*($J$10:$J$23=$L$10:$L$23)*($G$10:$G$23=BD$8)))*100 +SUM(($G$10:$G$23=$AH12)*($J$10:$J$23)*($O$10:$O$23=BD$8)+($O$10:$O$23=$AH12)*($L$10:$L$23)*($G$10:$G$23=BD$8)) -SUM(($G$10:$G$23=$AH12)*($L$10:$L$23)*($O$10:$O$23=BD$8)+($O$10:$O$23=$AH12)*($J$10:$J$23)*($G$10:$G$23=BD$8)) +SUM(($G$10:$G$23=$AH12)*($J$10:$J$23)*($O$10:$O$23=BD$8)+($O$10:$O$23=$AH12)*($L$10:$L$23)*($G$10:$G$23=BD$8))/100} -> -0.99
B14: 17 | C14: =VLOOKUP(B14,Aux!M:AH,4,0) -> 45827.75 | D14: =VLOOKUP(B14,Aux!M:AH,4,0) -> 45827.75 | F14: =IFERROR(VLOOKUP(G14,Aux!$A:$X,8,0),"") -> #VALUE! | G14: =VLOOKUP(B14,Aux!M:Y,5,0) -> Palmeiras | H14: =IFERROR(VLOOKUP(G14,Aux!$A:$C,3,0),"") -> #VALUE! | J14: 2 | K14: - | L14: 0 | N14: =IFERROR(VLOOKUP(O14,Aux!$A:$C,3,0),"") -> #VALUE! | O14: =VLOOKUP(B14,Aux!M:Y,6,0) -> Al-Ahly | P14: =IFERROR(VLOOKUP(O14,Aux!$A:$X,8,0),"") -> #VALUE! | R14: =VLOOKUP(B14,Aux!M:Y,7,0) -> MetLife Stadium | T14: =INDEX($AH$10:$AH$17,MATCH(3,$AY$10:$AY$16,0)) -> Inter Miami | U14: =IFERROR(VLOOKUP(T14,Aux!A:C,3,0),"") -> #VALUE! | W14: =VLOOKUP($T14,$AH$10:$AO$16,3,0) -> 3 | X14: =VLOOKUP($T14,$AH$10:$AO$16,4,0) -> 1 | Y14: =VLOOKUP($T14,$AH$10:$AO$16,5,0) -> 0 | Z14: =VLOOKUP($T14,$AH$10:$AO$16,6,0) -> 2 | AA14: =VLOOKUP($T14,$AH$10:$AO$16,7,0) -> 5 | AB14: =VLOOKUP($T14,$AH$10:$AO$16,8,0) -> 5 | AC14: =AA14-AB14 -> 0 | AG14: 3 | AH14: =VLOOKUP($AH$6&AG14,Aux!Z:AA,2,0) -> Palmeiras | AI14: =AK14+AL14+AM14 -> 3 | AJ14: =AK14*3+AL14 -> 7 | AK14: {=SUM(($G$10:$G$23=$AH14)*($J$10:$J$23>$L$10:$L$23)+($O$10:$O$23=$AH14)*($J$10:$J$23<$L$10:$L$23))} -> 2 | AL14: {=SUM(($G$10:$G$23=$AH14)*($J$10:$J$23=$L$10:$L$23)*($J$10:$J$23<>"")+($O$10:$O$23=$AH14)*($J$10:$J$23=$L$10:$L$23)*($J$10:$J$23<>""))} -> 1 | AM14: {=SUM(($G$10:$G$23=$AH14)*($J$10:$J$23<$L$10:$L$23)+($O$10:$O$23=$AH14)*($J$10:$J$23>$L$10:$L$23))} -> 0 | AN14: {=SUM(($G$10:$G$23=$AH14)*($J$10:$J$23)+($O$10:$O$23=$AH14)*($L$10:$L$23))} -> 6 | AO14: {=SUM(($G$10:$G$23=$AH14)*($L$10:$L$23)+($O$10:$O$23=$AH14)*($J$10:$J$23))} -> 3 | AP14: =AN14-AO14 -> 3 | AQ14: 0 | AR14: =+AW14+AV14+AU14 -> 7.10011 | AU14: =+AJ14 -> 7 | AV14: =SUMIFS($BA14:$BD14,$BA$6:$BD$6,AJ14)/1000 -> 0.10001 | AW14: =SUMIFS($BA14:$BD14,$BA$5:$BD$5,AV14)/1000000 -> 0.00010001 | AX14: =_xlfn.RANK.EQ(AJ14,$AJ$10:$AJ$16)+_xlfn.RANK.EQ(AR14,$AR$10:$AR$16)/10+_xlfn.RANK.EQ(AP14,$AP$10:$AP$16)/1000+_xlfn.RANK.EQ(AN14,$AN$10:$AN$16)/100000+_xlfn.RANK.EQ(AQ14,$AQ$10:$AQ$16)/100000+ROW()/1000000 -> 1.101034 | AY14: =_xlfn.RANK.EQ(AX14,$AX$10:$AX$16,1) -> 1 | BA14: {=(SUM(($G$10:$G$23=$AH14)*($J$10:$J$23>$L$10:$L$23)*($O$10:$O$23=BA$8)+($O$10:$O$23=$AH14)*($J$10:$J$23<$L$10:$L$23)*($G$10:$G$23=BA$8)))*300+ (SUM(($G$10:$G$23=$AH14)*($J$10:$J$23=$L$10:$L$23)*($O$10:$O$23=BA$8)+($O$10:$O$23=$AH14)*($J$10:$J$23=$L$10:$L$23)*($G$10:$G$23=BA$8)))*100 +SUM(($G$10:$G$23=$AH14)*($J$10:$J$23)*($O$10:$O$23=BA$8)+($O$10:$O$23=$AH14)*($L$10:$L$23)*($G$10:$G$23=BA$8)) -SUM(($G$10:$G$23=$AH14)*($L$10:$L$23)*($O$10:$O$23=BA$8)+($O$10:$O$23=$AH14)*($J$10:$J$23)*($G$10:$G$23=BA$8)) +SUM(($G$10:$G$23=$AH14)*($J$10:$J$23)*($O$10:$O$23=BA$8)+($O$10:$O$23=$AH14)*($L$10:$L$23)*($G$10:$G$23=BA$8))/100} -> 302.02 | BB14: {=(SUM(($G$10:$G$23=$AH14)*($J$10:$J$23>$L$10:$L$23)*($O$10:$O$23=BB$8)+($O$10:$O$23=$AH14)*($J$10:$J$23<$L$10:$L$23)*($G$10:$G$23=BB$8)))*300+ (SUM(($G$10:$G$23=$AH14)*($J$10:$J$23=$L$10:$L$23)*($O$10:$O$23=BB$8)+($O$10:$O$23=$AH14)*($J$10:$J$23=$L$10:$L$23)*($G$10:$G$23=BB$8)))*100 +SUM(($G$10:$G$23=$AH14)*($J$10:$J$23)*($O$10:$O$23=BB$8)+($O$10:$O$23=$AH14)*($L$10:$L$23)*($G$10:$G$23=BB$8)) -SUM(($G$10:$G$23=$AH14)*($L$10:$L$23)*($O$10:$O$23=BB$8)+($O$10:$O$23=$AH14)*($J$10:$J$23)*($G$10:$G$23=BB$8)) +SUM(($G$10:$G$23=$AH14)*($J$10:$J$23)*($O$10:$O$23=BB$8)+($O$10:$O$23=$AH14)*($L$10:$L$23)*($G$10:$G$23=BB$8))/100} -> 301.03 | BC14: {=(SUM(($G$10:$G$23=$AH14)*($J$10:$J$23>$L$10:$L$23)*($O$10:$O$23=BC$8)+($O$10:$O$23=$AH14)*($J$10:$J$23<$L$10:$L$23)*($G$10:$G$23=BC$8)))*300+ (SUM(($G$10:$G$23=$AH14)*($J$10:$J$23=$L$10:$L$23)*($O$10:$O$23=BC$8)+($O$10:$O$23=$AH14)*($J$10:$J$23=$L$10:$L$23)*($G$10:$G$23=BC$8)))*100 +SUM(($G$10:$G$23=$AH14)*($J$10:$J$23)*($O$10:$O$23=BC$8)+($O$10:$O$23=$AH14)*($L$10:$L$23)*($G$10:$G$23=BC$8)) -SUM(($G$10:$G$23=$AH14)*($L$10:$L$23)*($O$10:$O$23=BC$8)+($O$10:$O$23=$AH14)*($J$10:$J$23)*($G$10:$G$23=BC$8)) +SUM(($G$10:$G$23=$AH14)*($J$10:$J$23)*($O$10:$O$23=BC$8)+($O$10:$O$23=$AH14)*($L$10:$L$23)*($G$10:$G$23=BC$8))/100} -> 0 | BD14: {=(SUM(($G$10:$G$23=$AH14)*($J$10:$J$23>$L$10:$L$23)*($O$10:$O$23=BD$8)+($O$10:$O$23=$AH14)*($J$10:$J$23<$L$10:$L$23)*($G$10:$G$23=BD$8)))*300+ (SUM(($G$10:$G$23=$AH14)*($J$10:$J$23=$L$10:$L$23)*($O$10:$O$23=BD$8)+($O$10:$O$23=$AH14)*($J$10:$J$23=$L$10:$L$23)*($G$10:$G$23=BD$8)))*100 +SUM(($G$10:$G$23=$AH14)*($J$10:$J$23)*($O$10:$O$23=BD$8)+($O$10:$O$23=$AH14)*($L$10:$L$23)*($G$10:$G$23=BD$8)) -SUM(($G$10:$G$23=$AH14)*($L$10:$L$23)*($O$10:$O$23=BD$8)+($O$10:$O$23=$AH14)*($J$10:$J$23)*($G$10:$G$23=BD$8)) +SUM(($G$10:$G$23=$AH14)*($J$10:$J$23)*($O$10:$O$23=BD$8)+($O$10:$O$23=$AH14)*($L$10:$L$23)*($G$10:$G$23=BD$8))/100} -> 100.01
B16: 18 | C16: =VLOOKUP(B16,Aux!M:AH,4,0) -> 45827.875 | D16: =VLOOKUP(B16,Aux!M:AH,4,0) -> 45827.875 | F16: =IFERROR(VLOOKUP(G16,Aux!$A:$X,8,0),"") -> #VALUE! | G16: =VLOOKUP(B16,Aux!M:Y,5,0) -> Inter Miami | H16: =IFERROR(VLOOKUP(G16,Aux!$A:$C,3,0),"") -> #VALUE! | J16: 1 | K16: - | L16: 2 | N16: =IFERROR(VLOOKUP(O16,Aux!$A:$C,3,0),"") -> #VALUE! | O16: =VLOOKUP(B16,Aux!M:Y,6,0) -> Porto | P16: =IFERROR(VLOOKUP(O16,Aux!$A:$X,8,0),"") -> #VALUE! | R16: =VLOOKUP(B16,Aux!M:Y,7,0) -> Mercedes-Benz Stadium | T16: =INDEX($AH$10:$AH$17,MATCH(4,$AY$10:$AY$16,0)) -> Al-Ahly | U16: =IFERROR(VLOOKUP(T16,Aux!A:C,3,0),"") -> #VALUE! | W16: =VLOOKUP($T16,$AH$10:$AO$16,3,0) -> 0 | X16: =VLOOKUP($T16,$AH$10:$AO$16,4,0) -> 0 | Y16: =VLOOKUP($T16,$AH$10:$AO$16,5,0) -> 0 | Z16: =VLOOKUP($T16,$AH$10:$AO$16,6,0) -> 3 | AA16: =VLOOKUP($T16,$AH$10:$AO$16,7,0) -> 0 | AB16: =VLOOKUP($T16,$AH$10:$AO$16,8,0) -> 6 | AC16: =AA16-AB16 -> -6 | AG16: 4 | AH16: =VLOOKUP($AH$6&AG16,Aux!Z:AA,2,0) -> Porto | AI16: =AK16+AL16+AM16 -> 3 | AJ16: =AK16*3+AL16 -> 7 | AK16: {=SUM(($G$10:$G$23=$AH16)*($J$10:$J$23>$L$10:$L$23)+($O$10:$O$23=$AH16)*($J$10:$J$23<$L$10:$L$23))} -> 2 | AL16: {=SUM(($G$10:$G$23=$AH16)*($J$10:$J$23=$L$10:$L$23)*($J$10:$J$23<>"")+($O$10:$O$23=$AH16)*($J$10:$J$23=$L$10:$L$23)*($J$10:$J$23<>""))} -> 1 | AM16: {=SUM(($G$10:$G$23=$AH16)*($J$10:$J$23<$L$10:$L$23)+($O$10:$O$23=$AH16)*($J$10:$J$23>$L$10:$L$23))} -> 0 | AN16: {=SUM(($G$10:$G$23=$AH16)*($J$10:$J$23)+($O$10:$O$23=$AH16)*($L$10:$L$23))} -> 5 | AO16: {=SUM(($G$10:$G$23=$AH16)*($L$10:$L$23)+($O$10:$O$23=$AH16)*($J$10:$J$23))} -> 2 | AP16: =AN16-AO16 -> 3 | AQ16: 0 | AR16: =+AW16+AV16+AU16 -> 7.10011 | AU16: =+AJ16 -> 7 | AV16: =SUMIFS($BA16:$BD16,$BA$6:$BD$6,AJ16)/1000 -> 0.10001 | AW16: =SUMIFS($BA16:$BD16,$BA$5:$BD$5,AV16)/1000000 -> 0.00010001 | AX16: =_xlfn.RANK.EQ(AJ16,$AJ$10:$AJ$16)+_xlfn.RANK.EQ(AR16,$AR$10:$AR$16)/10+_xlfn.RANK.EQ(AP16,$AP$10:$AP$16)/1000+_xlfn.RANK.EQ(AN16,$AN$10:$AN$16)/100000+_xlfn.RANK.EQ(AQ16,$AQ$10:$AQ$16)/100000+ROW()/1000000 -> 1.101046 | AY16: =_xlfn.RANK.EQ(AX16,$AX$10:$AX$16,1) -> 2 | BA16: {=(SUM(($G$10:$G$23=$AH16)*($J$10:$J$23>$L$10:$L$23)*($O$10:$O$23=BA$8)+($O$10:$O$23=$AH16)*($J$10:$J$23<$L$10:$L$23)*($G$10:$G$23=BA$8)))*300+ (SUM(($G$10:$G$23=$AH16)*($J$10:$J$23=$L$10:$L$23)*($O$10:$O$23=BA$8)+($O$10:$O$23=$AH16)*($J$10:$J$23=$L$10:$L$23)*($G$10:$G$23=BA$8)))*100 +SUM(($G$10:$G$23=$AH16)*($J$10:$J$23)*($O$10:$O$23=BA$8)+($O$10:$O$23=$AH16)*($L$10:$L$23)*($G$10:$G$23=BA$8)) -SUM(($G$10:$G$23=$AH16)*($L$10:$L$23)*($O$10:$O$23=BA$8)+($O$10:$O$23=$AH16)*($J$10:$J$23)*($G$10:$G$23=BA$8)) +SUM(($G$10:$G$23=$AH16)*($J$10:$J$23)*($O$10:$O$23=BA$8)+($O$10:$O$23=$AH16)*($L$10:$L$23)*($G$10:$G$23=BA$8))/100} -> 302.02 | BB16: {=(SUM(($G$10:$G$23=$AH16)*($J$10:$J$23>$L$10:$L$23)*($O$10:$O$23=BB$8)+($O$10:$O$23=$AH16)*($J$10:$J$23<$L$10:$L$23)*($G$10:$G$23=BB$8)))*300+ (SUM(($G$10:$G$23=$AH16)*($J$10:$J$23=$L$10:$L$23)*($O$10:$O$23=BB$8)+($O$10:$O$23=$AH16)*($J$10:$J$23=$L$10:$L$23)*($G$10:$G$23=BB$8)))*100 +SUM(($G$10:$G$23=$AH16)*($J$10:$J$23)*($O$10:$O$23=BB$8)+($O$10:$O$23=$AH16)*($L$10:$L$23)*($G$10:$G$23=BB$8)) -SUM(($G$10:$G$23=$AH16)*($L$10:$L$23)*($O$10:$O$23=BB$8)+($O$10:$O$23=$AH16)*($J$10:$J$23)*($G$10:$G$23=BB$8)) +SUM(($G$10:$G$23=$AH16)*($J$10:$J$23)*($O$10:$O$23=BB$8)+($O$10:$O$23=$AH16)*($L$10:$L$23)*($G$10:$G$23=BB$8))/100} -> 301.02 | BC16: {=(SUM(($G$10:$G$23=$AH16)*($J$10:$J$23>$L$10:$L$23)*($O$10:$O$23=BC$8)+($O$10:$O$23=$AH16)*($J$10:$J$23<$L$10:$L$23)*($G$10:$G$23=BC$8)))*300+ (SUM(($G$10:$G$23=$AH16)*($J$10:$J$23=$L$10:$L$23)*($O$10:$O$23=BC$8)+($O$10:$O$23=$AH16)*($J$10:$J$23=$L$10:$L$23)*($G$10:$G$23=BC$8)))*100 +SUM(($G$10:$G$23=$AH16)*($J$10:$J$23)*($O$10:$O$23=BC$8)+($O$10:$O$23=$AH16)*($L$10:$L$23)*($G$10:$G$23=BC$8)) -SUM(($G$10:$G$23=$AH16)*($L$10:$L$23)*($O$10:$O$23=BC$8)+($O$10:$O$23=$AH16)*($J$10:$J$23)*($G$10:$G$23=BC$8)) +SUM(($G$10:$G$23=$AH16)*($J$10:$J$23)*($O$10:$O$23=BC$8)+($O$10:$O$23=$AH16)*($L$10:$L$23)*($G$10:$G$23=BC$8))/100} -> 100.01 | BD16: {=(SUM(($G$10:$G$23=$AH16)*($J$10:$J$23>$L$10:$L$23)*($O$10:$O$23=BD$8)+($O$10:$O$23=$AH16)*($J$10:$J$23<$L$10:$L$23)*($G$10:$G$23=BD$8)))*300+ (SUM(($G$10:$G$23=$AH16)*($J$10:$J$23=$L$10:$L$23)*($O$10:$O$23=BD$8)+($O$10:$O$23=$AH16)*($J$10:$J$23=$L$10:$L$23)*($G$10:$G$23=BD$8)))*100 +SUM(($G$10:$G$23=$AH16)*($J$10:$J$23)*($O$10:$O$23=BD$8)+($O$10:$O$23=$AH16)*($L$10:$L$23)*($G$10:$G$23=BD$8)) -SUM(($G$10:$G$23=$AH16)*($L$10:$L$23)*($O$10:$O$23=BD$8)+($O$10:$O$23=$AH16)*($J$10:$J$23)*($G$10:$G$23=BD$8)) +SUM(($G$10:$G$23=$AH16)*($J$10:$J$23)*($O$10:$O$23=BD$8)+($O$10:$O$23=$AH16)*($L$10:$L$23)*($G$10:$G$23=BD$8))/100} -> 0
B18: 35 | C18: =VLOOKUP(B18,Aux!M:AH,4,0) -> 45832.125 | D18: =VLOOKUP(B18,Aux!M:AH,4,0) -> 45832.125 | F18: =IFERROR(VLOOKUP(G18,Aux!$A:$X,8,0),"") -> #VALUE! | G18: =VLOOKUP(B18,Aux!M:Y,5,0) -> Inter Miami | H18: =IFERROR(VLOOKUP(G18,Aux!$A:$C,3,0),"") -> #VALUE! | J18: 2 | K18: - | L18: 3 | N18: =IFERROR(VLOOKUP(O18,Aux!$A:$C,3,0),"") -> #VALUE! | O18: =VLOOKUP(B18,Aux!M:Y,6,0) -> Palmeiras | P18: =IFERROR(VLOOKUP(O18,Aux!$A:$X,8,0),"") -> #VALUE! | R18: =VLOOKUP(B18,Aux!M:Y,7,0) -> Hard Rock Stadium
B20: 36 | C20: =VLOOKUP(B20,Aux!M:AH,4,0) -> 45832.125 | D20: =VLOOKUP(B20,Aux!M:AH,4,0) -> 45832.125 | F20: =IFERROR(VLOOKUP(G20,Aux!$A:$X,8,0),"") -> #VALUE! | G20: =VLOOKUP(B20,Aux!M:Y,5,0) -> Porto | H20: =IFERROR(VLOOKUP(G20,Aux!$A:$C,3,0),"") -> #VALUE! | J20: 2 | K20: - | L20: 0 | N20: =IFERROR(VLOOKUP(O20,Aux!$A:$C,3,0),"") -> #VALUE! | O20: =VLOOKUP(B20,Aux!M:Y,6,0) -> Al-Ahly | P20: =IFERROR(VLOOKUP(O20,Aux!$A:$X,8,0),"") -> #VALUE! | R20: =VLOOKUP(B20,Aux!M:Y,7,0) -> MetLife Stadium
W21: Aprendiz de Excel
W23: Vídeo YouTube

Sheet B
A1: Aprendiz de Excel - Mundial de Clubes 2025
AY5: 2º | BA5: =VLOOKUP(BA8,$AH$10:$AW$16,15,0) -> 0.10001 | BB5: =VLOOKUP(BB8,$AH$10:$AW$16,15,0) -> 0.10001 | BC5: =VLOOKUP(BC8,$AH$10:$AW$16,15,0) -> 0 | BD5: =VLOOKUP(BD8,$AH$10:$AW$16,15,0) -> 0
AH6: B | AY6: 1º | BA6: =VLOOKUP(BA8,$AH$10:$AW$16,14,0) -> 7 | BB6: =VLOOKUP(BB8,$AH$10:$AW$16,14,0) -> 7 | BC6: =VLOOKUP(BC8,$AH$10:$AW$16,14,0) -> 3 | BD6: =VLOOKUP(BD8,$AH$10:$AW$16,14,0) -> 0
B7: # | C7: Fechas | D7: Horas | E7: PARTIDOS | R7: Estadios | T7: POSICIONES
W8: Pts. | X8: Gan. | Y8: Emp. | Z8: Per. | AA8: GF | AB8: GC | AC8: Dif. | AH8: País | AI8: J | AJ8: Pts. | AK8: Gan. | AL8: Emp. | AM8: Per. | AN8: GF | AO8: GC | AP8: DG | AQ8: JL | AR8: ED | AU8: 1º Criterio | AV8: 2º Criterio | AW8: 3º Criterio | BA8: =AH10 -> Paris Saint-Germain | BB8: =AH12 -> Atlético de Madrid | BC8: =AH14 -> Botafogo | BD8: =AH16 -> Seattle Sounders
B9: {=_xlfn.REDUCE("",_xlfn.TAKE(_xlfn._xlws.FILTER(Aux!M:T,Aux!T:T=AH6),,1),_xlfn.LAMBDA(_xlpm.t,_xlpm.p,_xlfn.VSTACK(_xlpm.t,_xlpm.p,"")))}
B10: 3 | C10: =VLOOKUP(B10,Aux!M:AH,4,0) -> 45823.875 | D10: =VLOOKUP(B10,Aux!M:AH,4,0) -> 45823.875 | F10: =IFERROR(VLOOKUP(G10,Aux!$A:$X,8,0),"") -> #VALUE! | G10: =VLOOKUP(B10,Aux!M:Y,5,0) -> Paris Saint-Germain | H10: =IFERROR(VLOOKUP(G10,Aux!$A:$C,3,0),"") -> #VALUE! | J10: 1 | K10: - | L10: 1 | N10: =IFERROR(VLOOKUP(O10,Aux!$A:$C,3,0),"") -> #VALUE! | O10: =VLOOKUP(B10,Aux!M:Y,6,0) -> Atlético de Madrid | P10: =IFERROR(VLOOKUP(O10,Aux!$A:$X,8,0),"") -> #VALUE! | R10: =VLOOKUP(B10,Aux!M:Y,7,0) -> Rose Bowl | T10: =INDEX($AH$10:$AH$17,MATCH(1,$AY$10:$AY$16,0)) -> Paris Saint-Germain | U10: =IFERROR(VLOOKUP(T10,Aux!A:C,3,0),"") -> #VALUE! | W10: =VLOOKUP($T10,$AH$10:$AO$16,3,0) -> 7 | X10: =VLOOKUP($T10,$AH$10:$AO$16,4,0) -> 2 | Y10: =VLOOKUP($T10,$AH$10:$AO$16,5,0) -> 1 | Z10: =VLOOKUP($T10,$AH$10:$AO$16,6,0) -> 0 | AA10: =VLOOKUP($T10,$AH$10:$AO$16,7,0) -> 7 | AB10: =VLOOKUP($T10,$AH$10:$AO$16,8,0) -> 1 | AC10: =AA10-AB10 -> 6 | AG10: 1 | AH10: =VLOOKUP($AH$6&AG10,Aux!Z:AA,2,0) -> Paris Saint-Germain | AI10: =AK10+AL10+AM10 -> 3 | AJ10: =AK10*3+AL10 -> 7 | AK10: {=SUM(($G$10:$G$23=$AH10)*($J$10:$J$23>$L$10:$L$23)+($O$10:$O$23=$AH10)*($J$10:$J$23<$L$10:$L$23))} -> 2 | AL10: {=SUM(($G$10:$G$23=$AH10)*($J$10:$J$23=$L$10:$L$23)*($J$10:$J$23<>"")+($O$10:$O$23=$AH10)*($J$10:$J$23=$L$10:$L$23)*($J$10:$J$23<>""))} -> 1 | AM10: {=SUM(($G$10:$G$23=$AH10)*($J$10:$J$23<$L$10:$L$23)+($O$10:$O$23=$AH10)*($J$10:$J$23>$L$10:$L$23))} -> 0 | AN10: {=SUM(($G$10:$G$23=$AH10)*($J$10:$J$23)+($O$10:$O$23=$AH10)*($L$10:$L$23))} -> 7 | AO10: {=SUM(($G$10:$G$23=$AH10)*($L$10:$L$23)+($O$10:$O$23=$AH10)*($J$10:$J$23))} -> 1 | AP10: =AN10-AO10 -> 6 | AQ10: 0 | AR10: =+AW10+AV10+AU10 -> 7.10011 | AU10: =+AJ10 -> 7 | AV10: =SUMIFS($BA10:$BD10,$BA$6:$BD$6,AJ10)/1000 -> 0.10001 | AW10: =SUMIFS($BA10:$BD10,$BA$5:$BD$5,AV10)/1000000 -> 0.00010001 | AX10: =_xlfn.RANK.EQ(AJ10,$AJ$10:$AJ$16)+_xlfn.RANK.EQ(AR10,$AR$10:$AR$16)/10+_xlfn.RANK.EQ(AP10,$AP$10:$AP$16)/1000+_xlfn.RANK.EQ(AN10,$AN$10:$AN$16)/100000+_xlfn.RANK.EQ(AQ10,$AQ$10:$AQ$16)/100000+ROW()/1000000 -> 1.10103 | AY10: =_xlfn.RANK.EQ(AX10,$AX$10:$AX$16,1) -> 1 | BA10: {=(SUM(($G$10:$G$23=$AH10)*($J$10:$J$23>$L$10:$L$23)*($O$10:$O$23=BA$8)+($O$10:$O$23=$AH10)*($J$10:$J$23<$L$10:$L$23)*($G$10:$G$23=BA$8)))*300+ (SUM(($G$10:$G$23=$AH10)*($J$10:$J$23=$L$10:$L$23)*($O$10:$O$23=BA$8)+($O$10:$O$23=$AH10)*($J$10:$J$23=$L$10:$L$23)*($G$10:$G$23=BA$8)))*100 +SUM(($G$10:$G$23=$AH10)*($J$10:$J$23)*($O$10:$O$23=BA$8)+($O$10:$O$23=$AH10)*($L$10:$L$23)*($G$10:$G$23=BA$8)) -SUM(($G$10:$G$23=$AH10)*($L$10:$L$23)*($O$10:$O$23=BA$8)+($O$10:$O$23=$AH10)*($J$10:$J$23)*($G$10:$G$23=BA$8)) +SUM(($G$10:$G$23=$AH10)*($J$10:$J$23)*($O$10:$O$23=BA$8)+($O$10:$O$23=$AH10)*($L$10:$L$23)*($G$10:$G$23=BA$8))/100} -> 0 | BB10: {=(SUM(($G$10:$G$23=$AH10)*($J$10:$J$23>$L$10:$L$23)*($O$10:$O$23=BB$8)+($O$10:$O$23=$AH10)*($J$10:$J$23<$L$10:$L$23)*($G$10:$G$23=BB$8)))*300+ (SUM(($G$10:$G$23=$AH10)*($J$10:$J$23=$L$10:$L$23)*($O$10:$O$23=BB$8)+($O$10:$O$23=$AH10)*($J$10:$J$23=$L$10:$L$23)*($G$10:$G$23=BB$8)))*100 +SUM(($G$10:$G$23=$AH10)*($J$10:$J$23)*($O$10:$O$23=BB$8)+($O$10:$O$23=$AH10)*($L$10:$L$23)*($G$10:$G$23=BB$8)) -SUM(($G$10:$G$23=$AH10)*($L$10:$L$23)*($O$10:$O$23=BB$8)+($O$10:$O$23=$AH10)*($J$10:$J$23)*($G$10:$G$23=BB$8)) +SUM(($G$10:$G$23=$AH10)*($J$10:$J$23)*($O$10:$O$23=BB$8)+($O$10:$O$23=$AH10)*($L$10:$L$23)*($G$10:$G$23=BB$8))/100} -> 100.01 | BC10: {=(SUM(($G$10:$G$23=$AH10)*($J$10:$J$23>$L$10:$L$23)*($O$10:$O$23=BC$8)+($O$10:$O$23=$AH10)*($J$10:$J$23<$L$10:$L$23)*($G$10:$G$23=BC$8)))*300+ (SUM(($G$10:$G$23=$AH10)*($J$10:$J$23=$L$10:$L$23)*($O$10:$O$23=BC$8)+($O$10:$O$23=$AH10)*($J$10:$J$23=$L$10:$L$23)*($G$10:$G$23=BC$8)))*100 +SUM(($G$10:$G$23=$AH10)*($J$10:$J$23)*($O$10:$O$23=BC$8)+($O$10:$O$23=$AH10)*($L$10:$L$23)*($G$10:$G$23=BC$8)) -SUM(($G$10:$G$23=$AH10)*($L$10:$L$23)*($O$10:$O$23=BC$8)+($O$10:$O$23=$AH10)*($J$10:$J$23)*($G$10:$G$23=BC$8)) +SUM(($G$10:$G$23=$AH10)*($J$10:$J$23)*($O$10:$O$23=BC$8)+($O$10:$O$23=$AH10)*($L$10:$L$23)*($G$10:$G$23=BC$8))/100} -> 302.02 | BD10: {=(SUM(($G$10:$G$23=$AH10)*($J$10:$J$23>$L$10:$L$23)*($O$10:$O$23=BD$8)+($O$10:$O$23=$AH10)*($J$10:$J$23<$L$10:$L$23)*($G$10:$G$23=BD$8)))*300+ (SUM(($G$10:$G$23=$AH10)*($J$10:$J$23=$L$10:$L$23)*($O$10:$O$23=BD$8)+($O$10:$O$23=$AH10)*($J$10:$J$23=$L$10:$L$23)*($G$10:$G$23=BD$8)))*100 +SUM(($G$10:$G$23=$AH10)*($J$10:$J$23)*($O$10:$O$23=BD$8)+($O$10:$O$23=$AH10)*($L$10:$L$23)*($G$10:$G$23=BD$8)) -SUM(($G$10:$G$23=$AH10)*($L$10:$L$23)*($O$10:$O$23=BD$8)+($O$10:$O$23=$AH10)*($J$10:$J$23)*($G$10:$G$23=BD$8)) +SUM(($G$10:$G$23=$AH10)*($J$10:$J$23)*($O$10:$O$23=BD$8)+($O$10:$O$23=$AH10)*($L$10:$L$23)*($G$10:$G$23=BD$8))/100} -> 304.04
B12: 5 | C12: =VLOOKUP(B12,Aux!M:AH,4,0) -> 45824.167 | D12: =VLOOKUP(B12,Aux!M:AH,4,0) -> 45824.167 | F12: =IFERROR(VLOOKUP(G12,Aux!$A:$X,8,0),"") -> #VALUE! | G12: =VLOOKUP(B12,Aux!M:Y,5,0) -> Botafogo | H12: =IFERROR(VLOOKUP(G12,Aux!$A:$C,3,0),"") -> #VALUE! | J12: 2 | K12: - | L12: 0 | N12: =IFERROR(VLOOKUP(O12,Aux!$A:$C,3,0),"") -> #VALUE! | O12: =VLOOKUP(B12,Aux!M:Y,6,0) -> Seattle Sounders | P12: =IFERROR(VLOOKUP(O12,Aux!$A:$X,8,0),"") -> #VALUE! | R12: =VLOOKUP(B12,Aux!M:Y,7,0) -> Lumen Field | T12: =INDEX($AH$10:$AH$17,MATCH(2,$AY$10:$AY$16,0)) -> Atlético de Madrid | U12: =IFERROR(VLOOKUP(T12,Aux!A:C,3,0),"") -> #VALUE! | W12: =VLOOKUP($T12,$AH$10:$AO$16,3,0) -> 7 | X12: =VLOOKUP($T12,$AH$10:$AO$16,4,0) -> 2 | Y12: =VLOOKUP($T12,$AH$10:$AO$16,5,0) -> 1 | Z12: =VLOOKUP($T12,$AH$10:$AO$16,6,0) -> 0 | AA12: =VLOOKUP($T12,$AH$10:$AO$16,7,0) -> 4 | AB12: =VLOOKUP($T12,$AH$10:$AO$16,8,0) -> 2 | AC12: =AA12-AB12 -> 2 | AG12: 2 | AH12: =VLOOKUP($AH$6&AG12,Aux!Z:AA,2,0) -> Atlético de Madrid | AI12: =AK12+AL12+AM12 -> 3 | AJ12: =AK12*3+AL12 -> 7 | AK12: {=SUM(($G$10:$G$23=$AH12)*($J$10:$J$23>$L$10:$L$23)+($O$10:$O$23=$AH12)*($J$10:$J$23<$L$10:$L$23))} -> 2 | AL12: {=SUM(($G$10:$G$23=$AH12)*($J$10:$J$23=$L$10:$L$23)*($J$10:$J$23<>"")+($O$10:$O$23=$AH12)*($J$10:$J$23=$L$10:$L$23)*($J$10:$J$23<>""))} -> 1 | AM12: {=SUM(($G$10:$G$23=$AH12)*($J$10:$J$23<$L$10:$L$23)+($O$10:$O$23=$AH12)*($J$10:$J$23>$L$10:$L$23))} -> 0 | AN12: {=SUM(($G$10:$G$23=$AH12)*($J$10:$J$23)+($O$10:$O$23=$AH12)*($L$10:$L$23))} -> 4 | AO12: {=SUM(($G$10:$G$23=$AH12)*($L$10:$L$23)+($O$10:$O$23=$AH12)*($J$10:$J$23))} -> 2 | AP12: =AN12-AO12 -> 2 | AQ12: 0 | AR12: =+AW12+AV12+AU12 -> 7.10011 | AU12: =+AJ12 -> 7 | AV12: =SUMIFS($BA12:$BD12,$BA$6:$BD$6,AJ12)/1000 -> 0.10001 | AW12: =SUMIFS($BA12:$BD12,$BA$5:$BD$5,AV12)/1000000 -> 0.00010001 | AX12: =_xlfn.RANK.EQ(AJ12,$AJ$10:$AJ$16)+_xlfn.RANK.EQ(AR12,$AR$10:$AR$16)/10+_xlfn.RANK.EQ(AP12,$AP$10:$AP$16)/1000+_xlfn.RANK.EQ(AN12,$AN$10:$AN$16)/100000+_xlfn.RANK.EQ(AQ12,$AQ$10:$AQ$16)/100000+ROW()/1000000 -> 1.102042 | AY12: =_xlfn.RANK.EQ(AX12,$AX$10:$AX$16,1) -> 2 | BA12: {=(SUM(($G$10:$G$23=$AH12)*($J$10:$J$23>$L$10:$L$23)*($O$10:$O$23=BA$8)+($O$10:$O$23=$AH12)*($J$10:$J$23<$L$10:$L$23)*($G$10:$G$23=BA$8)))*300+ (SUM(($G$10:$G$23=$AH12)*($J$10:$J$23=$L$10:$L$23)*($O$10:$O$23=BA$8)+($O$10:$O$23=$AH12)*($J$10:$J$23=$L$10:$L$23)*($G$10:$G$23=BA$8)))*100 +SUM(($G$10:$G$23=$AH12)*($J$10:$J$23)*($O$10:$O$23=BA$8)+($O$10:$O$23=$AH12)*($L$10:$L$23)*($G$10:$G$23=BA$8)) -SUM(($G$10:$G$23=$AH12)*($L$10:$L$23)*($O$10:$O$23=BA$8)+($O$10:$O$23=$AH12)*($J$10:$J$23)*($G$10:$G$23=BA$8)) +SUM(($G$10:$G$23=$AH12)*($J$10:$J$23)*($O$10:$O$23=BA$8)+($O$10:$O$23=$AH12)*($L$10:$L$23)*($G$10:$G$23=BA$8))/100} -> 100.01 | BB12: {=(SUM(($G$10:$G$23=$AH12)*($J$10:$J$23>$L$10:$L$23)*($O$10:$O$23=BB$8)+($O$10:$O$23=$AH12)*($J$10:$J$23<$L$10:$L$23)*($G$10:$G$23=BB$8)))*300+ (SUM(($G$10:$G$23=$AH12)*($J$10:$J$23=$L$10:$L$23)*($O$10:$O$23=BB$8)+($O$10:$O$23=$AH12)*($J$10:$J$23=$L$10:$L$23)*($G$10:$G$23=BB$8)))*100 +SUM(($G$10:$G$23=$AH12)*($J$10:$J$23)*($O$10:$O$23=BB$8)+($O$10:$O$23=$AH12)*($L$10:$L$23)*($G$10:$G$23=BB$8)) -SUM(($G$10:$G$23=$AH12)*($L$10:$L$23)*($O$10:$O$23=BB$8)+($O$10:$O$23=$AH12)*($J$10:$J$23)*($G$10:$G$23=BB$8)) +SUM(($G$10:$G$23=$AH12)*($J$10:$J$23)*($O$10:$O$23=BB$8)+($O$10:$O$23=$AH12)*($L$10:$L$23)*($G$10:$G$23=BB$8))/100} -> 0 | BC12: {=(SUM(($G$10:$G$23=$AH12)*($J$10:$J$23>$L$10:$L$23)*($O$10:$O$23=BC$8)+($O$10:$O$23=$AH12)*($J$10:$J$23<$L$10:$L$23)*($G$10:$G$23=BC$8)))*300+ (SUM(($G$10:$G$23=$AH12)*($J$10:$J$23=$L$10:$L$23)*($O$10:$O$23=BC$8)+($O$10:$O$23=$AH12)*($J$10:$J$23=$L$10:$L$23)*($G$10:$G$23=BC$8)))*100 +SUM(($G$10:$G$23=$AH12)*($J$10:$J$23)*($O$10:$O$23=BC$8)+($O$10:$O$23=$AH12)*($L$10:$L$23)*($G$10:$G$23=BC$8)) -SUM(($G$10:$G$23=$AH12)*($L$10:$L$23)*($O$10:$O$23=BC$8)+($O$10:$O$23=$AH12)*($J$10:$J$23)*($G$10:$G$23=BC$8)) +SUM(($G$10:$G$23=$AH12)*($J$10:$J$23)*($O$10:$O$23=BC$8)+($O$10:$O$23=$AH12)*($L$10:$L$23)*($G$10:$G$23=BC$8))/100} -> 301.01 | BD12: {=(SUM(($G$10:$G$23=$AH12)*($J$10:$J$23>$L$10:$L$23)*($O$10:$O$23=BD$8)+($O$10:$O$23=$AH12)*($J$10:$J$23<$L$10:$L$23)*($G$10:$G$23=BD$8)))*300+ (SUM(($G$10:$G$23=$AH12)*($J$10:$J$23=$L$10:$L$23)*($O$10:$O$23=BD$8)+($O$10:$O$23=$AH12)*($J$10:$J$23=$L$10:$L$23)*($G$10:$G$23=BD$8)))*100 +SUM(($G$10:$G$23=$AH12)*($J$10:$J$23)*($O$10:$O$23=BD$8)+($O$10:$O$23=$AH12)*($L$10:$L$23)*($G$10:$G$23=BD$8)) -SUM(($G$10:$G$23=$AH12)*($L$10:$L$23)*($O$10:$O$23=BD$8)+($O$10:$O$23=$AH12)*($J$10:$J$23)*($G$10:$G$23=BD$8)) +SUM(($G$10:$G$23=$AH12)*($J$10:$J$23)*($O$10:$O$23=BD$8)+($O$10:$O$23=$AH12)*($L$10:$L$23)*($G$10:$G$23=BD$8))/100} -> 301.02
B14: 19 | C14: =VLOOKUP(B14,Aux!M:AH,4,0) -> 45828 | D14: =VLOOKUP(B14,Aux!M:AH,4,0) -> 45828 | F14: =IFERROR(VLOOKUP(G14,Aux!$A:$X,8,0),"") -> #VALUE! | G14: =VLOOKUP(B14,Aux!M:Y,5,0) -> Seattle Sounders | H14: =IFERROR(VLOOKUP(G14,Aux!$A:$C,3,0),"") -> #VALUE! | J14: 1 | K14: - | L14: 2 | N14: =IFERROR(VLOOKUP(O14,Aux!$A:$C,3,0),"") -> #VALUE! | O14: =VLOOKUP(B14,Aux!M:Y,6,0) -> Atlético de Madrid | P14: =IFERROR(VLOOKUP(O14,Aux!$A:$X,8,0),"") -> #VALUE! | R14: =VLOOKUP(B14,Aux!M:Y,7,0) -> Lumen Field | T14: =INDEX($AH$10:$AH$17,MATCH(3,$AY$10:$AY$16,0)) -> Botafogo | U14: =IFERROR(VLOOKUP(T14,Aux!A:C,3,0),"") -> #VALUE! | W14: =VLOOKUP($T14,$AH$10:$AO$16,3,0) -> 3 | X14: =VLOOKUP($T14,$AH$10:$AO$16,4,0) -> 1 | Y14: =VLOOKUP($T14,$AH$10:$AO$16,5,0) -> 0 | Z14: =VLOOKUP($T14,$AH$10:$AO$16,6,0) -> 2 | AA14: =VLOOKUP($T14,$AH$10:$AO$16,7,0) -> 2 | AB14: =VLOOKUP($T14,$AH$10:$AO$16,8,0) -> 3 | AC14: =AA14-AB14 -> -1 | AG14: 3 | AH14: =VLOOKUP($AH$6&AG14,Aux!Z:AA,2,0) -> Botafogo | AI14: =AK14+AL14+AM14 -> 3 | AJ14: =AK14*3+AL14 -> 3 | AK14: {=SUM(($G$10:$G$23=$AH14)*($J$10:$J$23>$L$10:$L$23)+($O$10:$O$23=$AH14)*($J$10:$J$23<$L$10:$L$23))} -> 1 | AL14: {=SUM(($G$10:$G$23=$AH14)*($J$10:$J$23=$L$10:$L$23)*($J$10:$J$23<>"")+($O$10:$O$23=$AH14)*($J$10:$J$23=$L$10:$L$23)*($J$10:$J$23<>""))} -> 0 | AM14: {=SUM(($G$10:$G$23=$AH14)*($J$10:$J$23<$L$10:$L$23)+($O$10:$O$23=$AH14)*($J$10:$J$23>$L$10:$L$23))} -> 2 | AN14: {=SUM(($G$10:$G$23=$AH14)*($J$10:$J$23)+($O$10:$O$23=$AH14)*($L$10:$L$23))} -> 2 | AO14: {=SUM(($G$10:$G$23=$AH14)*($L$10:$L$23)+($O$10:$O$23=$AH14)*($J$10:$J$23))} -> 3 | AP14: =AN14-AO14 -> -1 | AQ14: 0 | AR14: =+AW14+AV14+AU14 -> 3.000302 | AU14: =+AJ14 -> 3 | AV14: =SUMIFS($BA14:$BD14,$BA$6:$BD$6,AJ14)/1000 -> 0 | AW14: =SUMIFS($BA14:$BD14,$BA$5:$BD$5,AV14)/1000000 -> 0.00030202 | AX14: =_xlfn.RANK.EQ(AJ14,$AJ$10:$AJ$16)+_xlfn.RANK.EQ(AR14,$AR$10:$AR$16)/10+_xlfn.RANK.EQ(AP14,$AP$10:$AP$16)/1000+_xlfn.RANK.EQ(AN14,$AN$10:$AN$16)/100000+_xlfn.RANK.EQ(AQ14,$AQ$10:$AQ$16)/100000+ROW()/1000000 -> 3.303054 | AY14: =_xlfn.RANK.EQ(AX14,$AX$10:$AX$16,1) -> 3 | BA14: {=(SUM(($G$10:$G$23=$AH14)*($J$10:$J$23>$L$10:$L$23)*($O$10:$O$23=BA$8)+($O$10:$O$23=$AH14)*($J$10:$J$23<$L$10:$L$23)*($G$10:$G$23=BA$8)))*300+ (SUM(($G$10:$G$23=$AH14)*($J$10:$J$23=$L$10:$L$23)*($O$10:$O$23=BA$8)+($O$10:$O$23=$AH14)*($J$10:$J$23=$L$10:$L$23)*($G$10:$G$23=BA$8)))*100 +SUM(($G$10:$G$23=$AH14)*($J$10:$J$23)*($O$10:$O$23=BA$8)+($O$10:$O$23=$AH14)*($L$10:$L$23)*($G$10:$G$23=BA$8)) -SUM(($G$10:$G$23=$AH14)*($L$10:$L$23)*($O$10:$O$23=BA$8)+($O$10:$O$23=$AH14)*($J$10:$J$23)*($G$10:$G$23=BA$8)) +SUM(($G$10:$G$23=$AH14)*($J$10:$J$23)*($O$10:$O$23=BA$8)+($O$10:$O$23=$AH14)*($L$10:$L$23)*($G$10:$G$23=BA$8))/100} -> -2 | BB14: {=(SUM(($G$10:$G$23=$AH14)*($J$10:$J$23>$L$10:$L$23)*($O$10:$O$23=BB$8)+($O$10:$O$23=$AH14)*($J$10:$J$23<$L$10:$L$23)*($G$10:$G$23=BB$8)))*300+ (SUM(($G$10:$G$23=$AH14)*($J$10:$J$23=$L$10:$L$23)*($O$10:$O$23=BB$8)+($O$10:$O$23=$AH14)*($J$10:$J$23=$L$10:$L$23)*($G$10:$G$23=BB$8)))*100 +SUM(($G$10:$G$23=$AH14)*($J$10:$J$23)*($O$10:$O$23=BB$8)+($O$10:$O$23=$AH14)*($L$10:$L$23)*($G$10:$G$23=BB$8)) -SUM(($G$10:$G$23=$AH14)*($L$10:$L$23)*($O$10:$O$23=BB$8)+($O$10:$O$23=$AH14)*($J$10:$J$23)*($G$10:$G$23=BB$8)) +SUM(($G$10:$G$23=$AH14)*($J$10:$J$23)*($O$10:$O$23=BB$8)+($O$10:$O$23=$AH14)*($L$10:$L$23)*($G$10:$G$23=BB$8))/100} -> -1 | BC14: {=(SUM(($G$10:$G$23=$AH14)*($J$10:$J$23>$L$10:$L$23)*($O$10:$O$23=BC$8)+($O$10:$O$23=$AH14)*($J$10:$J$23<$L$10:$L$23)*($G$10:$G$23=BC$8)))*300+ (SUM(($G$10:$G$23=$AH14)*($J$10:$J$23=$L$10:$L$23)*($O$10:$O$23=BC$8)+($O$10:$O$23=$AH14)*($J$10:$J$23=$L$10:$L$23)*($G$10:$G$23=BC$8)))*100 +SUM(($G$10:$G$23=$AH14)*($J$10:$J$23)*($O$10:$O$23=BC$8)+($O$10:$O$23=$AH14)*($L$10:$L$23)*($G$10:$G$23=BC$8)) -SUM(($G$10:$G$23=$AH14)*($L$10:$L$23)*($O$10:$O$23=BC$8)+($O$10:$O$23=$AH14)*($J$10:$J$23)*($G$10:$G$23=BC$8)) +SUM(($G$10:$G$23=$AH14)*($J$10:$J$23)*($O$10:$O$23=BC$8)+($O$10:$O$23=$AH14)*($L$10:$L$23)*($G$10:$G$23=BC$8))/100} -> 0 | BD14: {=(SUM(($G$10:$G$23=$AH14)*($J$10:$J$23>$L$10:$L$23)*($O$10:$O$23=BD$8)+($O$10:$O$23=$AH14)*($J$10:$J$23<$L$10:$L$23)*($G$10:$G$23=BD$8)))*300+ (SUM(($G$10:$G$23=$AH14)*($J$10:$J$23=$L$10:$L$23)*($O$10:$O$23=BD$8)+($O$10:$O$23=$AH14)*($J$10:$J$23=$L$10:$L$23)*($G$10:$G$23=BD$8)))*100 +SUM(($G$10:$G$23=$AH14)*($J$10:$J$23)*($O$10:$O$23=BD$8)+($O$10:$O$23=$AH14)*($L$10:$L$23)*($G$10:$G$23=BD$8)) -SUM(($G$10:$G$23=$AH14)*($L$10:$L$23)*($O$10:$O$23=BD$8)+($O$10:$O$23=$AH14)*($J$10:$J$23)*($G$10:$G$23=BD$8)) +SUM(($G$10:$G$23=$AH14)*($J$10:$J$23)*($O$10:$O$23=BD$8)+($O$10:$O$23=$AH14)*($L$10:$L$23)*($G$10:$G$23=BD$8))/100} -> 302.02
B16: 20 | C16: =VLOOKUP(B16,Aux!M:AH,4,0) -> 45828.125 | D16: =VLOOKUP(B16,Aux!M:AH,4,0) -> 45828.125 | F16: =IFERROR(VLOOKUP(G16,Aux!$A:$X,8,0),"") -> #VALUE! | G16: =VLOOKUP(B16,Aux!M:Y,5,0) -> Paris Saint-Germain | H16: =IFERROR(VLOOKUP(G16,Aux!$A:$C,3,0),"") -> #VALUE! | J16: 2 | K16: - | L16: 0 | N16: =IFERROR(VLOOKUP(O16,Aux!$A:$C,3,0),"") -> #VALUE! | O16: =VLOOKUP(B16,Aux!M:Y,6,0) -> Botafogo | P16: =IFERROR(VLOOKUP(O16,Aux!$A:$X,8,0),"") -> #VALUE! | R16: =VLOOKUP(B16,Aux!M:Y,7,0) -> Rose Bowl | T16: =INDEX($AH$10:$AH$17,MATCH(4,$AY$10:$AY$16,0)) -> Seattle Sounders | U16: =IFERROR(VLOOKUP(T16,Aux!A:C,3,0),"") -> #VALUE! | W16: =VLOOKUP($T16,$AH$10:$AO$16,3,0) -> 0 | X16: =VLOOKUP($T16,$AH$10:$AO$16,4,0) -> 0 | Y16: =VLOOKUP($T16,$AH$10:$AO$16,5,0) -> 0 | Z16: =VLOOKUP($T16,$AH$10:$AO$16,6,0) -> 3 | AA16: =VLOOKUP($T16,$AH$10:$AO$16,7,0) -> 1 | AB16: =VLOOKUP($T16,$AH$10:$AO$16,8,0) -> 8 | AC16: =AA16-AB16 -> -7 | AG16: 4 | AH16: =VLOOKUP($AH$6&AG16,Aux!Z:AA,2,0) -> Seattle Sounders | AI16: =AK16+AL16+AM16 -> 3 | AJ16: =AK16*3+AL16 -> 0 | AK16: {=SUM(($G$10:$G$23=$AH16)*($J$10:$J$23>$L$10:$L$23)+($O$10:$O$23=$AH16)*($J$10:$J$23<$L$10:$L$23))} -> 0 | AL16: {=SUM(($G$10:$G$23=$AH16)*($J$10:$J$23=$L$10:$L$23)*($J$10:$J$23<>"")+($O$10:$O$23=$AH16)*($J$10:$J$23=$L$10:$L$23)*($J$10:$J$23<>""))} -> 0 | AM16: {=SUM(($G$10:$G$23=$AH16)*($J$10:$J$23<$L$10:$L$23)+($O$10:$O$23=$AH16)*($J$10:$J$23>$L$10:$L$23))} -> 3 | AN16: {=SUM(($G$10:$G$23=$AH16)*($J$10:$J$23)+($O$10:$O$23=$AH16)*($L$10:$L$23))} -> 1 | AO16: {=SUM(($G$10:$G$23=$AH16)*($L$10:$L$23)+($O$10:$O$23=$AH16)*($J$10:$J$23))} -> 8 | AP16: =AN16-AO16 -> -7 | AQ16: 0 | AR16: =+AW16+AV16+AU16 -> -2e-06 | AU16: =+AJ16 -> 0 | AV16: =SUMIFS($BA16:$BD16,$BA$6:$BD$6,AJ16)/1000 -> 0 | AW16: =SUMIFS($BA16:$BD16,$BA$5:$BD$5,AV16)/1000000 -> -2e-06 | AX16: =_xlfn.RANK.EQ(AJ16,$AJ$10:$AJ$16)+_xlfn.RANK.EQ(AR16,$AR$10:$AR$16)/10+_xlfn.RANK.EQ(AP16,$AP$10:$AP$16)/1000+_xlfn.RANK.EQ(AN16,$AN$10:$AN$16)/100000+_xlfn.RANK.EQ(AQ16,$AQ$10:$AQ$16)/100000+ROW()/1000000 -> 4.404066 | AY16: =_xlfn.RANK.EQ(AX16,$AX$10:$AX$16,1) -> 4 | BA16: {=(SUM(($G$10:$G$23=$AH16)*($J$10:$J$23>$L$10:$L$23)*($O$10:$O$23=BA$8)+($O$10:$O$23=$AH16)*($J$10:$J$23<$L$10:$L$23)*($G$10:$G$23=BA$8)))*300+ (SUM(($G$10:$G$23=$AH16)*($J$10:$J$23=$L$10:$L$23)*($O$10:$O$23=BA$8)+($O$10:$O$23=$AH16)*($J$10:$J$23=$L$10:$L$23)*($G$10:$G$23=BA$8)))*100 +SUM(($G$10:$G$23=$AH16)*($J$10:$J$23)*($O$10:$O$23=BA$8)+($O$10:$O$23=$AH16)*($L$10:$L$23)*($G$10:$G$23=BA$8)) -SUM(($G$10:$G$23=$AH16)*($L$10:$L$23)*($O$10:$O$23=BA$8)+($O$10:$O$23=$AH16)*($J$10:$J$23)*($G$10:$G$23=BA$8)) +SUM(($G$10:$G$23=$AH16)*($J$10:$J$23)*($O$10:$O$23=BA$8)+($O$10:$O$23=$AH16)*($L$10:$L$23)*($G$10:$G$23=BA$8))/100} -> -4 | BB16: {=(SUM(($G$10:$G$23=$AH16)*($J$10:$J$23>$L$10:$L$23)*($O$10:$O$23=BB$8)+($O$10:$O$23=$AH16)*($J$10:$J$23<$L$10:$L$23)*($G$10:$G$23=BB$8)))*300+ (SUM(($G$10:$G$23=$AH16)*($J$10:$J$23=$L$10:$L$23)*($O$10:$O$23=BB$8)+($O$10:$O$23=$AH16)*($J$10:$J$23=$L$10:$L$23)*($G$10:$G$23=BB$8)))*100 +SUM(($G$10:$G$23=$AH16)*($J$10:$J$23)*($O$10:$O$23=BB$8)+($O$10:$O$23=$AH16)*($L$10:$L$23)*($G$10:$G$23=BB$8)) -SUM(($G$10:$G$23=$AH16)*($L$10:$L$23)*($O$10:$O$23=BB$8)+($O$10:$O$23=$AH16)*($J$10:$J$23)*($G$10:$G$23=BB$8)) +SUM(($G$10:$G$23=$AH16)*($J$10:$J$23)*($O$10:$O$23=BB$8)+($O$10:$O$23=$AH16)*($L$10:$L$23)*($G$10:$G$23=BB$8))/100} -> -0.99 | BC16: {=(SUM(($G$10:$G$23=$AH16)*($J$10:$J$23>$L$10:$L$23)*($O$10:$O$23=BC$8)+($O$10:$O$23=$AH16)*($J$10:$J$23<$L$10:$L$23)*($G$10:$G$23=BC$8)))*300+ (SUM(($G$10:$G$23=$AH16)*($J$10:$J$23=$L$10:$L$23)*($O$10:$O$23=BC$8)+($O$10:$O$23=$AH16)*($J$10:$J$23=$L$10:$L$23)*($G$10:$G$23=BC$8)))*100 +SUM(($G$10:$G$23=$AH16)*($J$10:$J$23)*($O$10:$O$23=BC$8)+($O$10:$O$23=$AH16)*($L$10:$L$23)*($G$10:$G$23=BC$8)) -SUM(($G$10:$G$23=$AH16)*($L$10:$L$23)*($O$10:$O$23=BC$8)+($O$10:$O$23=$AH16)*($J$10:$J$23)*($G$10:$G$23=BC$8)) +SUM(($G$10:$G$23=$AH16)*($J$10:$J$23)*($O$10:$O$23=BC$8)+($O$10:$O$23=$AH16)*($L$10:$L$23)*($G$10:$G$23=BC$8))/100} -> -2 | BD16: {=(SUM(($G$10:$G$23=$AH16)*($J$10:$J$23>$L$10:$L$23)*($O$10:$O$23=BD$8)+($O$10:$O$23=$AH16)*($J$10:$J$23<$L$10:$L$23)*($G$10:$G$23=BD$8)))*300+ (SUM(($G$10:$G$23=$AH16)*($J$10:$J$23=$L$10:$L$23)*($O$10:$O$23=BD$8)+($O$10:$O$23=$AH16)*($J$10:$J$23=$L$10:$L$23)*($G$10:$G$23=BD$8)))*100 +SUM(($G$10:$G$23=$AH16)*($J$10:$J$23)*($O$10:$O$23=BD$8)+($O$10:$O$23=$AH16)*($L$10:$L$23)*($G$10:$G$23=BD$8)) -SUM(($G$10:$G$23=$AH16)*($L$10:$L$23)*($O$10:$O$23=BD$8)+($O$10:$O$23=$AH16)*($J$10:$J$23)*($G$10:$G$23=BD$8)) +SUM(($G$10:$G$23=$AH16)*($J$10:$J$23)*($O$10:$O$23=BD$8)+($O$10:$O$23=$AH16)*($L$10:$L$23)*($G$10:$G$23=BD$8))/100} -> 0
B18: 33 | C18: =VLOOKUP(B18,Aux!M:AH,4,0) -> 45831.875 | D18: =VLOOKUP(B18,Aux!M:AH,4,0) -> 45831.875 | F18: =IFERROR(VLOOKUP(G18,Aux!$A:$X,8,0),"") -> #VALUE! | G18: =VLOOKUP(B18,Aux!M:Y,5,0) -> Seattle Sounders | H18: =IFERROR(VLOOKUP(G18,Aux!$A:$C,3,0),"") -> #VALUE! | J18: 0 | K18: - | L18: 4 | N18: =IFERROR(VLOOKUP(O18,Aux!$A:$C,3,0),"") -> #VALUE! | O18: =VLOOKUP(B18,Aux!M:Y,6,0) -> Paris Saint-Germain | P18: =IFERROR(VLOOKUP(O18,Aux!$A:$X,8,0),"") -> #VALUE! | R18: =VLOOKUP(B18,Aux!M:Y,7,0) -> Lumen Field
B20: 34 | C20: =VLOOKUP(B20,Aux!M:AH,4,0) -> 45831.875 | D20: =VLOOKUP(B20,Aux!M:AH,4,0) -> 45831.875 | F20: =IFERROR(VLOOKUP(G20,Aux!$A:$X,8,0),"") -> #VALUE! | G20: =VLOOKUP(B20,Aux!M:Y,5,0) -> Atlético de Madrid | H20: =IFERROR(VLOOKUP(G20,Aux!$A:$C,3,0),"") -> #VALUE! | J20: 1 | K20: - | L20: 0 | N20: =IFERROR(VLOOKUP(O20,Aux!$A:$C,3,0),"") -> #VALUE! | O20: =VLOOKUP(B20,Aux!M:Y,6,0) -> Botafogo | P20: =IFERROR(VLOOKUP(O20,Aux!$A:$X,8,0),"") -> #VALUE! | R20: =VLOOKUP(B20,Aux!M:Y,7,0) -> Rose Bowl
W21: Aprendiz de Excel
W23: Vídeo YouTube

Sheet C
A1: Aprendiz de Excel - Mundial de Clubes 2025
AY5: 2º | BA5: =VLOOKUP(BA8,$AH$10:$AW$16,15,0) -> 0 | BB5: =VLOOKUP(BB8,$AH$10:$AW$16,15,0) -> 0 | BC5: =VLOOKUP(BC8,$AH$10:$AW$16,15,0) -> 0.10001 | BD5: =VLOOKUP(BD8,$AH$10:$AW$16,15,0) -> 0.10001
AH6: C | AY6: 1º | BA6: =VLOOKUP(BA8,$AH$10:$AW$16,14,0) -> 9 | BB6: =VLOOKUP(BB8,$AH$10:$AW$16,14,0) -> 0 | BC6: =VLOOKUP(BC8,$AH$10:$AW$16,14,0) -> 4 | BD6: =VLOOKUP(BD8,$AH$10:$AW$16,14,0) -> 4
B7: # | C7: Fechas | D7: Horas | E7: PARTIDOS | R7: Estadios | T7: POSICIONES
W8: Pts. | X8: Gan. | Y8: Emp. | Z8: Per. | AA8: GF | AB8: GC | AC8: Dif. | AH8: País | AI8: J | AJ8: Pts. | AK8: Gan. | AL8: Emp. | AM8: Per. | AN8: GF | AO8: GC | AP8: DG | AQ8: JL | AR8: ED | AU8: 1º Criterio | AV8: 2º Criterio | AW8: 3º Criterio | BA8: =AH10 -> Bayern Múnich | BB8: =AH12 -> Auckland City | BC8: =AH14 -> Boca Juniors | BD8: =AH16 -> Benfica
B9: {=_xlfn.REDUCE("",_xlfn.TAKE(_xlfn._xlws.FILTER(Aux!M:T,Aux!T:T=AH6),,1),_xlfn.LAMBDA(_xlpm.t,_xlpm.p,_xlfn.VSTACK(_xlpm.t,_xlpm.p,"")))}
B10: 2 | C10: =VLOOKUP(B10,Aux!M:AH,4,0) -> 45823.75 | D10: =VLOOKUP(B10,Aux!M:AH,4,0) -> 45823.75 | F10: =IFERROR(VLOOKUP(G10,Aux!$A:$X,8,0),"") -> #VALUE! | G10: =VLOOKUP(B10,Aux!M:Y,5,0) -> Bayern Múnich | H10: =IFERROR(VLOOKUP(G10,Aux!$A:$C,3,0),"") -> #VALUE! | J10: 5 | K10: - | L10: 0 | N10: =IFERROR(VLOOKUP(O10,Aux!$A:$C,3,0),"") -> #VALUE! | O10: =VLOOKUP(B10,Aux!M:Y,6,0) -> Auckland City | P10: =IFERROR(VLOOKUP(O10,Aux!$A:$X,8,0),"") -> #VALUE! | R10: =VLOOKUP(B10,Aux!M:Y,7,0) -> TQL Stadium | T10: =INDEX($AH$10:$AH$17,MATCH(1,$AY$10:$AY$16,0)) -> Bayern Múnich | U10: =IFERROR(VLOOKUP(T10,Aux!A:C,3,0),"") -> #VALUE! | W10: =VLOOKUP($T10,$AH$10:$AO$16,3,0) -> 9 | X10: =VLOOKUP($T10,$AH$10:$AO$16,4,0) -> 3 | Y10: =VLOOKUP($T10,$AH$10:$AO$16,5,0) -> 0 | Z10: =VLOOKUP($T10,$AH$10:$AO$16,6,0) -> 0 | AA10: =VLOOKUP($T10,$AH$10:$AO$16,7,0) -> 13 | AB10: =VLOOKUP($T10,$AH$10:$AO$16,8,0) -> 1 | AC10: =AA10-AB10 -> 12 | AG10: 1 | AH10: =VLOOKUP($AH$6&AG10,Aux!Z:AA,2,0) -> Bayern Múnich | AI10: =AK10+AL10+AM10 -> 3 | AJ10: =AK10*3+AL10 -> 9 | AK10: {=SUM(($G$10:$G$23=$AH10)*($J$10:$J$23>$L$10:$L$23)+($O$10:$O$23=$AH10)*($J$10:$J$23<$L$10:$L$23))} -> 3 | AL10: {=SUM(($G$10:$G$23=$AH10)*($J$10:$J$23=$L$10:$L$23)*($J$10:$J$23<>"")+($O$10:$O$23=$AH10)*($J$10:$J$23=$L$10:$L$23)*($J$10:$J$23<>""))} -> 0 | AM10: {=SUM(($G$10:$G$23=$AH10)*($J$10:$J$23<$L$10:$L$23)+($O$10:$O$23=$AH10)*($J$10:$J$23>$L$10:$L$23))} -> 0 | AN10: {=SUM(($G$10:$G$23=$AH10)*($J$10:$J$23)+($O$10:$O$23=$AH10)*($L$10:$L$23))} -> 13 | AO10: {=SUM(($G$10:$G$23=$AH10)*($L$10:$L$23)+($O$10:$O$23=$AH10)*($J$10:$J$23))} -> 1 | AP10: =AN10-AO10 -> 12 | AQ10: 0 | AR10: =+AW10+AV10+AU10 -> 9.000305 | AU10: =+AJ10 -> 9 | AV10: =SUMIFS($BA10:$BD10,$BA$6:$BD$6,AJ10)/1000 -> 0 | AW10: =SUMIFS($BA10:$BD10,$BA$5:$BD$5,AV10)/1000000 -> 0.00030505 | AX10: =_xlfn.RANK.EQ(AJ10,$AJ$10:$AJ$16)+_xlfn.RANK.EQ(AR10,$AR$10:$AR$16)/10+_xlfn.RANK.EQ(AP10,$AP$10:$AP$16)/1000+_xlfn.RANK.EQ(AN10,$AN$10:$AN$16)/100000+_xlfn.RANK.EQ(AQ10,$AQ$10:$AQ$16)/100000+ROW()/1000000 -> 1.10103 | AY10: =_xlfn.RANK.EQ(AX10,$AX$10:$AX$16,1) -> 1 | BA10: {=(SUM(($G$10:$G$23=$AH10)*($J$10:$J$23>$L$10:$L$23)*($O$10:$O$23=BA$8)+($O$10:$O$23=$AH10)*($J$10:$J$23<$L$10:$L$23)*($G$10:$G$23=BA$8)))*300+ (SUM(($G$10:$G$23=$AH10)*($J$10:$J$23=$L$10:$L$23)*($O$10:$O$23=BA$8)+($O$10:$O$23=$AH10)*($J$10:$J$23=$L$10:$L$23)*($G$10:$G$23=BA$8)))*100 +SUM(($G$10:$G$23=$AH10)*($J$10:$J$23)*($O$10:$O$23=BA$8)+($O$10:$O$23=$AH10)*($L$10:$L$23)*($G$10:$G$23=BA$8)) -SUM(($G$10:$G$23=$AH10)*($L$10:$L$23)*($O$10:$O$23=BA$8)+($O$10:$O$23=$AH10)*($J$10:$J$23)*($G$10:$G$23=BA$8)) +SUM(($G$10:$G$23=$AH10)*($J$10:$J$23)*($O$10:$O$23=BA$8)+($O$10:$O$23=$AH10)*($L$10:$L$23)*($G$10:$G$23=BA$8))/100} -> 0 | BB10: {=(SUM(($G$10:$G$23=$AH10)*($J$10:$J$23>$L$10:$L$23)*($O$10:$O$23=BB$8)+($O$10:$O$23=$AH10)*($J$10:$J$23<$L$10:$L$23)*($G$10:$G$23=BB$8)))*300+ (SUM(($G$10:$G$23=$AH10)*($J$10:$J$23=$L$10:$L$23)*($O$10:$O$23=BB$8)+($O$10:$O$23=$AH10)*($J$10:$J$23=$L$10:$L$23)*($G$10:$G$23=BB$8)))*100 +SUM(($G$10:$G$23=$AH10)*($J$10:$J$23)*($O$10:$O$23=BB$8)+($O$10:$O$23=$AH10)*($L$10:$L$23)*($G$10:$G$23=BB$8)) -SUM(($G$10:$G$23=$AH10)*($L$10:$L$23)*($O$10:$O$23=BB$8)+($O$10:$O$23=$AH10)*($J$10:$J$23)*($G$10:$G$23=BB$8)) +SUM(($G$10:$G$23=$AH10)*($J$10:$J$23)*($O$10:$O$23=BB$8)+($O$10:$O$23=$AH10)*($L$10:$L$23)*($G$10:$G$23=BB$8))/100} -> 305.05 | BC10: {=(SUM(($G$10:$G$23=$AH10)*($J$10:$J$23>$L$10:$L$23)*($O$10:$O$23=BC$8)+($O$10:$O$23=$AH10)*($J$10:$J$23<$L$10:$L$23)*($G$10:$G$23=BC$8)))*300+ (SUM(($G$10:$G$23=$AH10)*($J$10:$J$23=$L$10:$L$23)*($O$10:$O$23=BC$8)+($O$10:$O$23=$AH10)*($J$10:$J$23=$L$10:$L$23)*($G$10:$G$23=BC$8)))*100 +SUM(($G$10:$G$23=$AH10)*($J$10:$J$23)*($O$10:$O$23=BC$8)+($O$10:$O$23=$AH10)*($L$10:$L$23)*($G$10:$G$23=BC$8)) -SUM(($G$10:$G$23=$AH10)*($L$10:$L$23)*($O$10:$O$23=BC$8)+($O$10:$O$23=$AH10)*($J$10:$J$23)*($G$10:$G$23=BC$8)) +SUM(($G$10:$G$23=$AH10)*($J$10:$J$23)*($O$10:$O$23=BC$8)+($O$10:$O$23=$AH10)*($L$10:$L$23)*($G$10:$G$23=BC$8))/100} -> 304.04 | BD10: {=(SUM(($G$10:$G$23=$AH10)*($J$10:$J$23>$L$10:$L$23)*($O$10:$O$23=BD$8)+($O$10:$O$23=$AH10)*($J$10:$J$23<$L$10:$L$23)*($G$10:$G$23=BD$8)))*300+ (SUM(($G$10:$G$23=$AH10)*($J$10:$J$23=$L$10:$L$23)*($O$10:$O$23=BD$8)+($O$10:$O$23=$AH10)*($J$10:$J$23=$L$10:$L$23)*($G$10:$G$23=BD$8)))*100 +SUM(($G$10:$G$23=$AH10)*($J$10:$J$23)*($O$10:$O$23=BD$8)+($O$10:$O$23=$AH10)*($L$10:$L$23)*($G$10:$G$23=BD$8)) -SUM(($G$10:$G$23=$AH10)*($L$10:$L$23)*($O$10:$O$23=BD$8)+($O$10:$O$23=$AH10)*($J$10:$J$23)*($G$10:$G$23=BD$8)) +SUM(($G$10:$G$23=$AH10)*($J$10:$J$23)*($O$10:$O$23=BD$8)+($O$10:$O$23=$AH10)*($L$10:$L$23)*($G$10:$G$23=BD$8))/100} -> 303.04
B12: 7 | C12: =VLOOKUP(B12,Aux!M:AH,4,0) -> 45825 | D12: =VLOOKUP(B12,Aux!M:AH,4,0) -> 45825 | F12: =IFERROR(VLOOKUP(G12,Aux!$A:$X,8,0),"") -> #VALUE! | G12: =VLOOKUP(B12,Aux!M:Y,5,0) -> Boca Juniors | H12: =IFERROR(VLOOKUP(G12,Aux!$A:$C,3,0),"") -> #VALUE! | J12: 1 | K12: - | L12: 1 | N12: =IFERROR(VLOOKUP(O12,Aux!$A:$C,3,0),"") -> #VALUE! | O12: =VLOOKUP(B12,Aux!M:Y,6,0) -> Benfica | P12: =IFERROR(VLOOKUP(O12,Aux!$A:$X,8,0),"") -> #VALUE! | R12: =VLOOKUP(B12,Aux!M:Y,7,0) -> Hard Rock Stadium | T12: =INDEX($AH$10:$AH$17,MATCH(2,$AY$10:$AY$16,0)) -> Boca Juniors | U12: =IFERROR(VLOOKUP(T12,Aux!A:C,3,0),"") -> #VALUE! | W12: =VLOOKUP($T12,$AH$10:$AO$16,3,0) -> 4 | X12: =VLOOKUP($T12,$AH$10:$AO$16,4,0) -> 1 | Y12: =VLOOKUP($T12,$AH$10:$AO$16,5,0) -> 1 | Z12: =VLOOKUP($T12,$AH$10:$AO$16,6,0) -> 1 | AA12: =VLOOKUP($T12,$AH$10:$AO$16,7,0) -> 3 | AB12: =VLOOKUP($T12,$AH$10:$AO$16,8,0) -> 5 | AC12: =AA12-AB12 -> -2 | AG12: 2 | AH12: =VLOOKUP($AH$6&AG12,Aux!Z:AA,2,0) -> Auckland City | AI12: =AK12+AL12+AM12 -> 3 | AJ12: =AK12*3+AL12 -> 0 | AK12: {=SUM(($G$10:$G$23=$AH12)*($J$10:$J$23>$L$10:$L$23)+($O$10:$O$23=$AH12)*($J$10:$J$23<$L$10:$L$23))} -> 0 | AL12: {=SUM(($G$10:$G$23=$AH12)*($J$10:$J$23=$L$10:$L$23)*($J$10:$J$23<>"")+($O$10:$O$23=$AH12)*($J$10:$J$23=$L$10:$L$23)*($J$10:$J$23<>""))} -> 0 | AM12: {=SUM(($G$10:$G$23=$AH12)*($J$10:$J$23<$L$10:$L$23)+($O$10:$O$23=$AH12)*($J$10:$J$23>$L$10:$L$23))} -> 3 | AN12: {=SUM(($G$10:$G$23=$AH12)*($J$10:$J$23)+($O$10:$O$23=$AH12)*($L$10:$L$23))} -> 0 | AO12: {=SUM(($G$10:$G$23=$AH12)*($L$10:$L$23)+($O$10:$O$23=$AH12)*($J$10:$J$23))} -> 8 | AP12: =AN12-AO12 -> -8 | AQ12: 0 | AR12: =+AW12+AV12+AU12 -> -5e-06 | AU12: =+AJ12 -> 0 | AV12: =SUMIFS($BA12:$BD12,$BA$6:$BD$6,AJ12)/1000 -> 0 | AW12: =SUMIFS($BA12:$BD12,$BA$5:$BD$5,AV12)/1000000 -> -5e-06 | AX12: =_xlfn.RANK.EQ(AJ12,$AJ$10:$AJ$16)+_xlfn.RANK.EQ(AR12,$AR$10:$AR$16)/10+_xlfn.RANK.EQ(AP12,$AP$10:$AP$16)/1000+_xlfn.RANK.EQ(AN12,$AN$10:$AN$16)/100000+_xlfn.RANK.EQ(AQ12,$AQ$10:$AQ$16)/100000+ROW()/1000000 -> 4.404062 | AY12: =_xlfn.RANK.EQ(AX12,$AX$10:$AX$16,1) -> 4 | BA12: {=(SUM(($G$10:$G$23=$AH12)*($J$10:$J$23>$L$10:$L$23)*($O$10:$O$23=BA$8)+($O$10:$O$23=$AH12)*($J$10:$J$23<$L$10:$L$23)*($G$10:$G$23=BA$8)))*300+ (SUM(($G$10:$G$23=$AH12)*($J$10:$J$23=$L$10:$L$23)*($O$10:$O$23=BA$8)+($O$10:$O$23=$AH12)*($J$10:$J$23=$L$10:$L$23)*($G$10:$G$23=BA$8)))*100 +SUM(($G$10:$G$23=$AH12)*($J$10:$J$23)*($O$10:$O$23=BA$8)+($O$10:$O$23=$AH12)*($L$10:$L$23)*($G$10:$G$23=BA$8)) -SUM(($G$10:$G$23=$AH12)*($L$10:$L$23)*($O$10:$O$23=BA$8)+($O$10:$O$23=$AH12)*($J$10:$J$23)*($G$10:$G$23=BA$8)) +SUM(($G$10:$G$23=$AH12)*($J$10:$J$23)*($O$10:$O$23=BA$8)+($O$10:$O$23=$AH12)*($L$10:$L$23)*($G$10:$G$23=BA$8))/100} -> -5 | BB12: {=(SUM(($G$10:$G$23=$AH12)*($J$10:$J$23>$L$10:$L$23)*($O$10:$O$23=BB$8)+($O$10:$O$23=$AH12)*($J$10:$J$23<$L$10:$L$23)*($G$10:$G$23=BB$8)))*300+ (SUM(($G$10:$G$23=$AH12)*($J$10:$J$23=$L$10:$L$23)*($O$10:$O$23=BB$8)+($O$10:$O$23=$AH12)*($J$10:$J$23=$L$10:$L$23)*($G$10:$G$23=BB$8)))*100 +SUM(($G$10:$G$23=$AH12)*($J$10:$J$23)*($O$10:$O$23=BB$8)+($O$10:$O$23=$AH12)*($L$10:$L$23)*($G$10:$G$23=BB$8)) -SUM(($G$10:$G$23=$AH12)*($L$10:$L$23)*($O$10:$O$23=BB$8)+($O$10:$O$23=$AH12)*($J$10:$J$23)*($G$10:$G$23=BB$8)) +SUM(($G$10:$G$23=$AH12)*($J$10:$J$23)*($O$10:$O$23=BB$8)+($O$10:$O$23=$AH12)*($L$10:$L$23)*($G$10:$G$23=BB$8))/100} -> 0 | BC12: {=(SUM(($G$10:$G$23=$AH12)*($J$10:$J$23>$L$10:$L$23)*($O$10:$O$23=BC$8)+($O$10:$O$23=$AH12)*($J$10:$J$23<$L$10:$L$23)*($G$10:$G$23=BC$8)))*300+ (SUM(($G$10:$G$23=$AH12)*($J$10:$J$23=$L$10:$L$23)*($O$10:$O$23=BC$8)+($O$10:$O$23=$AH12)*($J$10:$J$23=$L$10:$L$23)*($G$10:$G$23=BC$8)))*100 +SUM(($G$10:$G$23=$AH12)*($J$10:$J$23)*($O$10:$O$23=BC$8)+($O$10:$O$23=$AH12)*($L$10:$L$23)*($G$10:$G$23=BC$8)) -SUM(($G$10:$G$23=$AH12)*($L$10:$L$23)*($O$10:$O$23=BC$8)+($O$10:$O$23=$AH12)*($J$10:$J$23)*($G$10:$G$23=BC$8)) +SUM(($G$10:$G$23=$AH12)*($J$10:$J$23)*($O$10:$O$23=BC$8)+($O$10:$O$23=$AH12)*($L$10:$L$23)*($G$10:$G$23=BC$8))/100} -> -2 | BD12: {=(SUM(($G$10:$G$23=$AH12)*($J$10:$J$23>$L$10:$L$23)*($O$10:$O$23=BD$8)+($O$10:$O$23=$AH12)*($J$10:$J$23<$L$10:$L$23)*($G$10:$G$23=BD$8)))*300+ (SUM(($G$10:$G$23=$AH12)*($J$10:$J$23=$L$10:$L$23)*($O$10:$O$23=BD$8)+($O$10:$O$23=$AH12)*($J$10:$J$23=$L$10:$L$23)*($G$10:$G$23=BD$8)))*100 +SUM(($G$10:$G$23=$AH12)*($J$10:$J$23)*($O$10:$O$23=BD$8)+($O$10:$O$23=$AH12)*($L$10:$L$23)*($G$10:$G$23=BD$8)) -SUM(($G$10:$G$23=$AH12)*($L$10:$L$23)*($O$10:$O$23=BD$8)+($O$10:$O$23=$AH12)*($J$10:$J$23)*($G$10:$G$23=BD$8)) +SUM(($G$10:$G$23=$AH12)*($J$10:$J$23)*($O$10:$O$23=BD$8)+($O$10:$O$23=$AH12)*($L$10:$L$23)*($G$10:$G$23=BD$8))/100} -> -1
